<?xml version="1.0" encoding="utf-8"?>
<!-- This URDF was automatically created by SolidWorks to URDF Exporter! Originally created by Stephen Brawner (brawner@gmail.com) 
     Commit Version: 1.6.0-4-g7f85cfe  Build Version: 1.6.7995.38578
     For more information, please see http://wiki.ros.org/sw_urdf_exporter -->
<robot
  name="xhand_left">
  <link
    name="left_hand_link">
    <inertial>
      <origin
        xyz="-0.00262275896666023 1.9282281868751E-07 0.0149884438278115"
        rpy="0 0 0" />
      <mass
        value="0.45039179" />
      <inertia
        ixx="0.0005625"
        ixy="0.00001183"
        ixz="-0.00000213"
        iyy="0.00041894"
        iyz="0.00003983"
        izz="0.00025265" />
    </inertial>
    <visual>
      <origin
        xyz="0 0 0"
        rpy="0 0 0" />
      <geometry>
        <mesh
          filename="package://xhand_left/meshes/left_hand_link.STL" />
      </geometry>
      <material
        name="">
        <color
          rgba="0.502 0.502 0.502 1" />
      </material>
    </visual>
    <collision>
      <origin
        xyz="0 0 0"
        rpy="0 0 0" />
      <geometry>
        <mesh
          filename="package://xhand_left/meshes/left_hand_link.STL" />
      </geometry>
    </collision>
  </link>
  <link
    name="left_hand_ee_link">
    <inertial>
      <origin
        xyz="-2.4094095195294E-16 1.06851030049852E-15 0"
        rpy="0 0 0" />
      <mass
        value="0.001" />
      <inertia
        ixx="1e-8"
        ixy="0"
        ixz="0"
        iyy="1e-8"
        iyz="0"
        izz="1e-8" />
    </inertial>
    <visual>
      <origin
        xyz="0 0 0"
        rpy="0 0 0" />
      <geometry>
        <mesh
          filename="package://xhand_left/meshes/left_hand_ee_link.STL" />
      </geometry>
      <material
        name="">
        <color
          rgba="0.055 0.055 0.063 1" />
      </material>
    </visual>
    <collision>
      <origin
        xyz="0 0 0"
        rpy="0 0 0" />
      <geometry>
        <mesh
          filename="package://xhand_left/meshes/left_hand_ee_link.STL" />
      </geometry>
    </collision>
  </link>
  <joint
    name="left_hand_ee_joint"
    type="fixed">
    <origin
      xyz="0 0 0.055"
      rpy="0 0 0" />
    <parent
      link="left_hand_link" />
    <child
      link="left_hand_ee_link" />
    <axis
      xyz="0 0 0" />
    <dynamics
      damping="0"
      friction="0" />
  </joint>
  <link
    name="left_hand_light_link">
    <inertial>
      <origin
        xyz="-0.0183865506879928 8.39101366445489E-06 -0.0149036292803927"
        rpy="0 0 0" />
      <mass
        value="0.001" />
      <inertia
        ixx="1e-8"
        ixy="0"
        ixz="0"
        iyy="1e-8"
        iyz="0"
        izz="1e-8" />
    </inertial>
    <visual>
      <origin
        xyz="0 0 0"
        rpy="0 0 0" />
      <geometry>
        <mesh
          filename="package://xhand_left/meshes/left_hand_light_link.STL" />
      </geometry>
      <material
        name="">
        <color
          rgba="0.553 0.671 1.0 1" />
      </material>
    </visual>
    <collision>
      <origin
        xyz="0 0 0"
        rpy="0 0 0" />
      <geometry>
        <mesh
          filename="package://xhand_left/meshes/left_hand_light_link.STL" />
      </geometry>
    </collision>
  </link>
  <joint
    name="left_hand_light_joint"
    type="fixed">
    <origin
      xyz="0 0 0.055"
      rpy="0 0 0" />
    <parent
      link="left_hand_link" />
    <child
      link="left_hand_light_link" />
    <axis
      xyz="0 0 0" />
    <dynamics
      damping="0"
      friction="0" />
  </joint>
  <link
    name="left_hand_dorsum_link">
    <inertial>
      <origin
        xyz="-0.0120398695826143 0.000363063295541019 0.00948041332787186"
        rpy="0 0 0" />
      <mass
        value="0.001" />
      <inertia
        ixx="1e-8"
        ixy="0"
        ixz="0"
        iyy="1e-8"
        iyz="0"
        izz="1e-8" />
    </inertial>
    <visual>
      <origin
        xyz="0 0 0"
        rpy="0 0 0" />
      <geometry>
        <mesh
          filename="package://xhand_left/meshes/left_hand_dorsum_link.STL" />
      </geometry>
      <material
        name="">
        <color
          rgba="0.941 0.941 0.941 1" />
      </material>
    </visual>
    <collision>
      <origin
        xyz="0 0 0"
        rpy="0 0 0" />
      <geometry>
        <mesh
          filename="package://xhand_left/meshes/left_hand_dorsum_link.STL" />
      </geometry>
    </collision>
  </link>
  <joint
    name="left_hand_dorsum_joint"
    type="fixed">
    <origin
      xyz="0 0 0.055"
      rpy="0 0 0" />
    <parent
      link="left_hand_link" />
    <child
      link="left_hand_dorsum_link" />
    <axis
      xyz="0 0 0" />
    <dynamics
      damping="0"
      friction="0" />
  </joint>
  <link
    name="left_hand_palm_link">
    <inertial>
      <origin
        xyz="0.00800297524186217 -0.0113238114713057 -0.00314825069563981"
        rpy="0 0 0" />
      <mass
        value="0.001" />
      <inertia
        ixx="1e-8"
        ixy="0"
        ixz="0"
        iyy="1e-8"
        iyz="0"
        izz="1e-8" />
    </inertial>
    <visual>
      <origin
        xyz="0 0 0"
        rpy="0 0 0" />
      <geometry>
        <mesh
          filename="package://xhand_left/meshes/left_hand_palm_link.STL" />
      </geometry>
      <material
        name="">
        <color
          rgba="0.055 0.055 0.063 1" />
      </material>
    </visual>
    <collision>
      <origin
        xyz="0 0 0"
        rpy="0 0 0" />
      <geometry>
        <mesh
          filename="package://xhand_left/meshes/left_hand_palm_link.STL" />
      </geometry>
    </collision>
  </link>
  <joint
    name="left_hand_palm_joint"
    type="fixed">
    <origin
      xyz="0 0 0.055"
      rpy="0 0 0" />
    <parent
      link="left_hand_link" />
    <child
      link="left_hand_palm_link" />
    <axis
      xyz="0 0 0" />
    <dynamics
      damping="0"
      friction="0" />
  </joint>
  <link
    name="left_hand_thumb_bend_link">
    <inertial>
      <origin
        xyz="1.30277733045858E-15 -0.0116298859000019 0.000800179555048956"
        rpy="0 0 0" />
      <mass
        value="0.00581743" />
      <inertia
        ixx="0.00000041"
        ixy="0.00000002"
        ixz="-0.00000003"
        iyy="0.0000004"
        iyz="0.00000005"
        izz="0.00000036" />
    </inertial>
    <visual>
      <origin
        xyz="0 0 0"
        rpy="0 0 0" />
      <geometry>
        <mesh
          filename="package://xhand_left/meshes/left_hand_thumb_bend_link.STL" />
      </geometry>
      <material
        name="">
        <color
          rgba="0.055 0.055 0.063 1" />
      </material>
    </visual>
    <collision>
      <origin
        xyz="0 0 0"
        rpy="0 0 0" />
      <geometry>
        <mesh
          filename="package://xhand_left/meshes/left_hand_thumb_bend_link.STL" />
      </geometry>
    </collision>
  </link>
  <joint
    name="left_hand_thumb_bend_joint"
    type="revolute">
    <origin
      xyz="0.020417 -0.028872 0.035928"
      rpy="-0.59468 0.149 0.21606" />
    <parent
      link="left_hand_link" />
    <child
      link="left_hand_thumb_bend_link" />
    <axis
      xyz="0 0 1" />
    <limit
      lower="0"
      upper="1.309"
      effort="0.295"
      velocity="2" />
    <dynamics
      damping="0"
      friction="0" />
  </joint>
  <link
    name="left_hand_thumb_rota_link1">
    <inertial>
      <origin
        xyz="-2.60430099629887E-06 -0.0165208164506705 -0.00460073109225927"
        rpy="0 0 0" />
      <mass
        value="0.07903209" />
      <inertia
        ixx="0.00001771"
        ixy="0.00000253"
        ixz="-0.00000182"
        iyy="0.00001035"
        iyz="0.0000045"
        izz="0.00001242" />
    </inertial>
    <visual>
      <origin
        xyz="0 0 0"
        rpy="0 0 0" />
      <geometry>
        <mesh
          filename="package://xhand_left/meshes/left_hand_thumb_rota_link1.STL" />
      </geometry>
      <material
        name="">
        <color
          rgba="0.055 0.055 0.063 1" />
      </material>
    </visual>
    <collision>
      <origin
        xyz="0 0 0"
        rpy="0 0 0" />
      <geometry>
        <mesh
          filename="package://xhand_left/meshes/left_hand_thumb_rota_link1.STL" />
      </geometry>
    </collision>
  </link>
  <joint
    name="left_hand_thumb_rota_joint1"
    type="revolute">
    <origin
      xyz="0 -0.0233 0.0055"
      rpy="0 0 0" />
    <parent
      link="left_hand_thumb_bend_link" />
    <child
      link="left_hand_thumb_rota_link1" />
    <axis
      xyz="-1 0 0" />
    <limit
      lower="0"
      upper="1.571"
      effort="0.884"
      velocity="1.696" />
    <dynamics
      damping="0"
      friction="0" />
  </joint>
  <link
    name="left_hand_thumb_rotaback_link1">
    <inertial>
      <origin
        xyz="1.0908827154394E-06 0.0153902775249481 -0.0199604413844877"
        rpy="0 0 0" />
      <mass
        value="0.001" />
      <inertia
        ixx="1e-8"
        ixy="0"
        ixz="0"
        iyy="1e-8"
        iyz="0"
        izz="1e-8" />
    </inertial>
    <visual>
      <origin
        xyz="0 0 0"
        rpy="0 0 0" />
      <geometry>
        <mesh
          filename="package://xhand_left/meshes/left_hand_thumb_rotaback_link1.STL" />
      </geometry>
      <material
        name="">
        <color
          rgba="0.941 0.941 0.941 1" />
      </material>
    </visual>
    <collision>
      <origin
        xyz="0 0 0"
        rpy="0 0 0" />
      <geometry>
        <mesh
          filename="package://xhand_left/meshes/left_hand_thumb_rotaback_link1.STL" />
      </geometry>
    </collision>
  </link>
  <joint
    name="left_hand_thumb_rotaback_joint1"
    type="fixed">
    <origin
      xyz="0 -0.0345 0"
      rpy="0 0 0" />
    <parent
      link="left_hand_thumb_rota_link1" />
    <child
      link="left_hand_thumb_rotaback_link1" />
    <axis
      xyz="0 0 0" />
    <dynamics
      damping="0"
      friction="0" />
  </joint>
  <link
    name="left_hand_thumb_rota_link2">
    <inertial>
      <origin
        xyz="-3.4267135698509E-05 -0.0221934789376313 -0.00361836297732096"
        rpy="0 0 0" />
      <mass
        value="0.03780633" />
      <inertia
        ixx="0.0000053"
        ixy="0.0000008"
        ixz="-0.00000053"
        iyy="0.00000305"
        iyz="0.00000143"
        izz="0.00000437" />
    </inertial>
    <visual>
      <origin
        xyz="0 0 0"
        rpy="0 0 0" />
      <geometry>
        <mesh
          filename="package://xhand_left/meshes/left_hand_thumb_rota_link2.STL" />
      </geometry>
      <material
        name="">
        <color
          rgba="0.055 0.055 0.063 1" />
      </material>
    </visual>
    <collision>
      <origin
        xyz="0 0 0"
        rpy="0 0 0" />
      <geometry>
        <mesh
          filename="package://xhand_left/meshes/left_hand_thumb_rota_link2.STL" />
      </geometry>
    </collision>
  </link>
  <joint
    name="left_hand_thumb_rota_joint2"
    type="revolute">
    <origin
      xyz="0 -0.0345 0"
      rpy="0 0 0" />
    <parent
      link="left_hand_thumb_rota_link1" />
    <child
      link="left_hand_thumb_rota_link2" />
    <axis
      xyz="-1 0 0" />
    <limit
      lower="0"
      upper="1.571"
      effort="0.302"
      velocity="1.98" />
    <dynamics
      damping="0"
      friction="0" />
  </joint>
  <link
    name="left_hand_thumb_rotaback_link2">
    <inertial>
      <origin
        xyz="3.26104113810288E-05 0.013606867156571 -0.0111115393929633"
        rpy="0 0 0" />
      <mass
        value="0.001" />
      <inertia
        ixx="1e-8"
        ixy="0"
        ixz="0"
        iyy="1e-8"
        iyz="0"
        izz="1e-8" />
    </inertial>
    <visual>
      <origin
        xyz="0 0 0"
        rpy="0 0 0" />
      <geometry>
        <mesh
          filename="package://xhand_left/meshes/left_hand_thumb_rotaback_link2.STL" />
      </geometry>
      <material
        name="">
        <color
          rgba="0.941 0.941 0.941 1" />
      </material>
    </visual>
    <collision>
      <origin
        xyz="0 0 0"
        rpy="0 0 0" />
      <geometry>
        <mesh
          filename="package://xhand_left/meshes/left_hand_thumb_rotaback_link2.STL" />
      </geometry>
    </collision>
  </link>
  <joint
    name="left_hand_thumb_rotaback_joint2"
    type="fixed">
    <origin
      xyz="0 -0.037416895853866 -0.00450000000000265"
      rpy="0 0 0" />
    <parent
      link="left_hand_thumb_rota_link2" />
    <child
      link="left_hand_thumb_rotaback_link2" />
    <axis
      xyz="0 0 0" />
    <dynamics
      damping="0"
      friction="0" />
  </joint>
  <link
    name="left_hand_thumb_rota_link3">
    <inertial>
      <origin
        xyz="-2.97704635382826E-06 -0.0156391842993251 -0.000426208558841776"
        rpy="0 0 0" />
      <mass
        value="0.00650707" />
      <inertia
        ixx="0.00000048"
        ixy="0.00000004"
        ixz="-0.00000002"
        iyy="0.00000032"
        iyz="0.00000012"
        izz="0.00000045" />
    </inertial>
    <visual>
      <origin
        xyz="0 0 0"
        rpy="0 0 0" />
      <geometry>
        <mesh
          filename="package://xhand_left/meshes/left_hand_thumb_rota_link3.STL" />
      </geometry>
      <material
        name="">
        <color
          rgba="0.055 0.055 0.063 1" />
      </material>
    </visual>
    <collision>
      <origin
        xyz="0 0 0"
        rpy="0 0 0" />
      <geometry>
        <mesh
          filename="package://xhand_left/meshes/left_hand_thumb_rota_link3.STL" />
      </geometry>
    </collision>
  </link>
  <joint
    name="left_hand_thumb_rota_joint3"
    type="revolute">
    <origin
      xyz="0 -0.037417 -0.0045"
      rpy="0 0 0" />
    <parent
      link="left_hand_thumb_rota_link2" />
    <child
      link="left_hand_thumb_rota_link3" />
    <axis
      xyz="-1 0 0" />
    <limit
      lower="0"
      upper="1.571"
      effort="0.295"
      velocity="2" />
    <dynamics
      damping="0"
      friction="0" />
  </joint>
  <link
    name="left_hand_thumb_rota_link4">
    <inertial>
      <origin
        xyz="2.49487930314984E-14 2.77555756156289E-17 2.77555756156289E-17"
        rpy="0 0 0" />
      <mass
        value="0.001" />
      <inertia
        ixx="1e-8"
        ixy="0"
        ixz="0"
        iyy="1e-8"
        iyz="0"
        izz="1e-8" />
    </inertial>
    <visual>
      <origin
        xyz="0 0 0"
        rpy="0 0 0" />
      <geometry>
        <mesh
          filename="package://xhand_left/meshes/left_hand_thumb_rota_link4.STL" />
      </geometry>
      <material
        name="">
        <color
          rgba="0.055 0.055 0.063 1" />
      </material>
    </visual>
    <collision>
      <origin
        xyz="0 0 0"
        rpy="0 0 0" />
      <geometry>
        <mesh
          filename="package://xhand_left/meshes/left_hand_thumb_rota_link4.STL" />
      </geometry>
    </collision>
  </link>
  <joint
    name="left_hand_thumb_rota_joint4"
    type="fixed">
    <origin
      xyz="0 -0.0181728187019031 0.00791114210898883"
      rpy="0 0 0" />
    <parent
      link="left_hand_thumb_rota_link3" />
    <child
      link="left_hand_thumb_rota_link4" />
    <axis
      xyz="0 0 0" />
    <dynamics
      damping="0"
      friction="0" />
  </joint>
  <link
    name="left_hand_thumb_rota_link5">
    <inertial>
      <origin
        xyz="2.49522624784504E-14 0 2.77555756156289E-17"
        rpy="0 0 0" />
      <mass
        value="0.001" />
      <inertia
        ixx="1e-8"
        ixy="0"
        ixz="0"
        iyy="1e-8"
        iyz="0"
        izz="1e-8" />
    </inertial>
    <visual>
      <origin
        xyz="0 0 0"
        rpy="0 0 0" />
      <geometry>
        <mesh
          filename="package://xhand_left/meshes/left_hand_thumb_rota_link5.STL" />
      </geometry>
      <material
        name="">
        <color
          rgba="0.055 0.055 0.063 1" />
      </material>
    </visual>
    <collision>
      <origin
        xyz="0 0 0"
        rpy="0 0 0" />
      <geometry>
        <mesh
          filename="package://xhand_left/meshes/left_hand_thumb_rota_link5.STL" />
      </geometry>
    </collision>
  </link>
  <joint
    name="left_hand_thumb_rota_joint5"
    type="fixed">
    <origin
      xyz="0 -0.0312512504715698 0"
      rpy="0 0 0" />
    <parent
      link="left_hand_thumb_rota_link3" />
    <child
      link="left_hand_thumb_rota_link5" />
    <axis
      xyz="0 0 0" />
    <dynamics
      damping="0"
      friction="0" />
  </joint>
  <link
    name="left_hand_index_bend_link">
    <inertial>
      <origin
        xyz="0.000800179555051457 -1.15879528195251E-15 0.0116298859000022"
        rpy="0 0 0" />
      <mass
        value="0.00581743" />
      <inertia
        ixx="0.00000043"
        ixy="0.0"
        ixz="-0.00000007"
        iyy="0.00000044"
        iyz="0.00000001"
        izz="0.00000033" />
    </inertial>
    <visual>
      <origin
        xyz="0 0 0"
        rpy="0 0 0" />
      <geometry>
        <mesh
          filename="package://xhand_left/meshes/left_hand_index_bend_link.STL" />
      </geometry>
      <material
        name="">
        <color
          rgba="0.055 0.055 0.063 1" />
      </material>
    </visual>
    <collision>
      <origin
        xyz="0 0 0"
        rpy="0 0 0" />
      <geometry>
        <mesh
          filename="package://xhand_left/meshes/left_hand_index_bend_link.STL" />
      </geometry>
    </collision>
  </link>
  <joint
    name="left_hand_index_bend_joint"
    type="revolute">
    <origin
      xyz="0.0045 -0.032961 0.096293"
      rpy="0 0 0" />
    <parent
      link="left_hand_link" />
    <child
      link="left_hand_index_bend_link" />
    <axis
      xyz="1 0 0" />
    <limit
      lower="-0.262"
      upper="1.396"
      effort="0.295"
      velocity="2" />
    <dynamics
      damping="0"
      friction="0" />
  </joint>
  <link
    name="left_hand_index_rota_link1">
    <inertial>
      <origin
        xyz="-0.00460077457082354 2.64958534040849E-06 0.0165208271005107"
        rpy="0 0 0" />
      <mass
        value="0.07903209" />
      <inertia
        ixx="0.00001597"
        ixy="-0.00000011"
        ixz="-0.00000056"
        iyy="0.00001854"
        iyz="-0.00000003"
        izz="0.00000598" />
    </inertial>
    <visual>
      <origin
        xyz="0 0 0"
        rpy="0 0 0" />
      <geometry>
        <mesh
          filename="package://xhand_left/meshes/left_hand_index_rota_link1.STL" />
      </geometry>
      <material
        name="">
        <color
          rgba="0.055 0.055 0.063 1" />
      </material>
    </visual>
    <collision>
      <origin
        xyz="0 0 0"
        rpy="0 0 0" />
      <geometry>
        <mesh
          filename="package://xhand_left/meshes/left_hand_index_rota_link1.STL" />
      </geometry>
    </collision>
  </link>
  <joint
    name="left_hand_index_rota_joint1"
    type="revolute">
    <origin
      xyz="0.0055 0 0.0233"
      rpy="0 0 0" />
    <parent
      link="left_hand_index_bend_link" />
    <child
      link="left_hand_index_rota_link1" />
    <axis
      xyz="0 1 0" />
    <limit
      lower="0"
      upper="1.571"
      effort="0.884"
      velocity="1.696" />
    <dynamics
      damping="0"
      friction="0" />
  </joint>
  <link
    name="left_hand_index_rotaback_link1">
    <inertial>
      <origin
        xyz="-0.0199604212773847 -1.11555281232661E-06 -0.0153905493818042"
        rpy="0 0 0" />
      <mass
        value="0.001" />
      <inertia
        ixx="1e-8"
        ixy="0"
        ixz="0"
        iyy="1e-8"
        iyz="0"
        izz="1e-8" />
    </inertial>
    <visual>
      <origin
        xyz="0 0 0"
        rpy="0 0 0" />
      <geometry>
        <mesh
          filename="package://xhand_left/meshes/left_hand_index_rotaback_link1.STL" />
      </geometry>
      <material
        name="">
        <color
          rgba="0.941 0.941 0.941 1" />
      </material>
    </visual>
    <collision>
      <origin
        xyz="0 0 0"
        rpy="0 0 0" />
      <geometry>
        <mesh
          filename="package://xhand_left/meshes/left_hand_index_rotaback_link1.STL" />
      </geometry>
    </collision>
  </link>
  <joint
    name="left_hand_index_rotaback_joint1"
    type="fixed">
    <origin
      xyz="0 0 0.0345"
      rpy="0 0 0" />
    <parent
      link="left_hand_index_rota_link1" />
    <child
      link="left_hand_index_rotaback_link1" />
    <axis
      xyz="0 0 0" />
    <dynamics
      damping="0"
      friction="0" />
  </joint>
  <link
    name="left_hand_index_rota_link2">
    <inertial>
      <origin
        xyz="-0.00361835935998423 3.42636230874216E-05 0.0221934729716251"
        rpy="0 0 0" />
      <mass
        value="0.03780633" />
      <inertia
        ixx="0.00000528"
        ixy="0.00000001"
        ixz="0.00000013"
        iyy="0.00000557"
        iyz="0.00000005"
        izz="0.00000187" />
    </inertial>
    <visual>
      <origin
        xyz="0 0 0"
        rpy="0 0 0" />
      <geometry>
        <mesh
          filename="package://xhand_left/meshes/left_hand_index_rota_link2.STL" />
      </geometry>
      <material
        name="">
        <color
          rgba="0.055 0.055 0.063 1" />
      </material>
    </visual>
    <collision>
      <origin
        xyz="0 0 0"
        rpy="0 0 0" />
      <geometry>
        <mesh
          filename="package://xhand_left/meshes/left_hand_index_rota_link2.STL" />
      </geometry>
    </collision>
  </link>
  <joint
    name="left_hand_index_rota_joint2"
    type="revolute">
    <origin
      xyz="0 0 0.0345"
      rpy="0 0 0" />
    <parent
      link="left_hand_index_rota_link1" />
    <child
      link="left_hand_index_rota_link2" />
    <axis
      xyz="0 1 0" />
    <limit
      lower="0"
      upper="1.571"
      effort="0.302"
      velocity="1.98" />
    <dynamics
      damping="0"
      friction="0" />
  </joint>
  <link
    name="left_hand_index_rotaback_link2">
    <inertial>
      <origin
        xyz="-0.0111115558244099 -3.27184187746826E-05 -0.0136070040557503"
        rpy="0 0 0" />
      <mass
        value="0.001" />
      <inertia
        ixx="1e-8"
        ixy="0"
        ixz="0"
        iyy="1e-8"
        iyz="0"
        izz="1e-8" />
    </inertial>
    <visual>
      <origin
        xyz="0 0 0"
        rpy="0 0 0" />
      <geometry>
        <mesh
          filename="package://xhand_left/meshes/left_hand_index_rotaback_link2.STL" />
      </geometry>
      <material
        name="">
        <color
          rgba="0.941 0.941 0.941 1" />
      </material>
    </visual>
    <collision>
      <origin
        xyz="0 0 0"
        rpy="0 0 0" />
      <geometry>
        <mesh
          filename="package://xhand_left/meshes/left_hand_index_rotaback_link2.STL" />
      </geometry>
    </collision>
  </link>
  <joint
    name="left_hand_index_rotaback_joint2"
    type="fixed">
    <origin
      xyz="-0.00450000000000022 0 0.0374168958538662"
      rpy="0 0 0" />
    <parent
      link="left_hand_index_rota_link2" />
    <child
      link="left_hand_index_rotaback_link2" />
    <axis
      xyz="0 0 0" />
    <dynamics
      damping="0"
      friction="0" />
  </joint>
  <link
    name="left_hand_index_rota_link3">
    <inertial>
      <origin
        xyz="-0.000426169432366642 2.78682943443548E-06 0.015639061700105"
        rpy="0 0 0" />
      <mass
        value="0.00650707" />
      <inertia
        ixx="0.00000052"
        ixy="0.0"
        ixz="0.00000002"
        iyy="0.00000049"
        iyz="-0.00000001"
        izz="0.00000025" />
    </inertial>
    <visual>
      <origin
        xyz="0 0 0"
        rpy="0 0 0" />
      <geometry>
        <mesh
          filename="package://xhand_left/meshes/left_hand_index_rota_link3.STL" />
      </geometry>
      <material
        name="">
        <color
          rgba="0.055 0.055 0.063 1" />
      </material>
    </visual>
    <collision>
      <origin
        xyz="0 0 0"
        rpy="0 0 0" />
      <geometry>
        <mesh
          filename="package://xhand_left/meshes/left_hand_index_rota_link3.STL" />
      </geometry>
    </collision>
  </link>
  <joint
    name="left_hand_index_rota_joint3"
    type="revolute">
    <origin
      xyz="-0.0045 0 0.037417"
      rpy="0 0 0" />
    <parent
      link="left_hand_index_rota_link2" />
    <child
      link="left_hand_index_rota_link3" />
    <axis
      xyz="0 1 0" />
    <limit
      lower="0"
      upper="1.571"
      effort="0.295"
      velocity="2" />
    <dynamics
      damping="0"
      friction="0" />
  </joint>
  <link
    name="left_hand_index_rota_link4">
    <inertial>
      <origin
        xyz="1.25247034965525E-15 -2.57016630200724E-14 0"
        rpy="0 0 0" />
      <mass
        value="0.001" />
      <inertia
        ixx="1e-8"
        ixy="0"
        ixz="0"
        iyy="1e-8"
        iyz="0"
        izz="1e-8" />
    </inertial>
    <visual>
      <origin
        xyz="0 0 0"
        rpy="0 0 0" />
      <geometry>
        <mesh
          filename="package://xhand_left/meshes/left_hand_index_rota_link4.STL" />
      </geometry>
      <material
        name="">
        <color
          rgba="0.055 0.055 0.063 1" />
      </material>
    </visual>
    <collision>
      <origin
        xyz="0 0 0"
        rpy="0 0 0" />
      <geometry>
        <mesh
          filename="package://xhand_left/meshes/left_hand_index_rota_link4.STL" />
      </geometry>
    </collision>
  </link>
  <joint
    name="left_hand_index_rota_joint4"
    type="fixed">
    <origin
      xyz="0.00791114210899898 0 0.0181728187018977"
      rpy="0 0 0" />
    <parent
      link="left_hand_index_rota_link3" />
    <child
      link="left_hand_index_rota_link4" />
    <axis
      xyz="0 0 0" />
    <dynamics
      damping="0"
      friction="0" />
  </joint>
  <link
    name="left_hand_index_rota_link5">
    <inertial>
      <origin
        xyz="1.25507243486922E-15 -2.52228793407028E-14 0"
        rpy="0 0 0" />
      <mass
        value="0.001" />
      <inertia
        ixx="1e-8"
        ixy="0"
        ixz="0"
        iyy="1e-8"
        iyz="0"
        izz="1e-8" />
    </inertial>
    <visual>
      <origin
        xyz="0 0 0"
        rpy="0 0 0" />
      <geometry>
        <mesh
          filename="package://xhand_left/meshes/left_hand_index_rota_link5.STL" />
      </geometry>
      <material
        name="">
        <color
          rgba="0.055 0.055 0.063 1" />
      </material>
    </visual>
    <collision>
      <origin
        xyz="0 0 0"
        rpy="0 0 0" />
      <geometry>
        <mesh
          filename="package://xhand_left/meshes/left_hand_index_rota_link5.STL" />
      </geometry>
    </collision>
  </link>
  <joint
    name="left_hand_index_rota_joint5"
    type="fixed">
    <origin
      xyz="0 0 0.0312512504715699"
      rpy="0 0 0" />
    <parent
      link="left_hand_index_rota_link3" />
    <child
      link="left_hand_index_rota_link5" />
    <axis
      xyz="0 0 0" />
    <dynamics
      damping="0"
      friction="0" />
  </joint>
  <link
    name="left_hand_mid_bend_link">
    <inertial>
      <origin
        xyz="0.000800179555044959 -1.22298005056365E-15 0.0116298859000074"
        rpy="0 0 0" />
      <mass
        value="0.00581743" />
      <inertia
        ixx="0.00000043"
        ixy="0.0"
        ixz="-0.00000004"
        iyy="0.00000042"
        iyz="0.00000001"
        izz="0.00000032" />
    </inertial>
    <visual>
      <origin
        xyz="0 0 0"
        rpy="0 0 0" />
      <geometry>
        <mesh
          filename="package://xhand_left/meshes/left_hand_mid_bend_link.STL" />
      </geometry>
      <material
        name="">
        <color
          rgba="0.055 0.055 0.063 1" />
      </material>
    </visual>
    <collision>
      <origin
        xyz="0 0 0"
        rpy="0 0 0" />
      <geometry>
        <mesh
          filename="package://xhand_left/meshes/left_hand_mid_bend_link.STL" />
      </geometry>
    </collision>
  </link>
  <joint
    name="left_hand_mid_bend_joint"
    type="revolute">
    <origin
      xyz="0.0045 -0.0086396 0.098793"
      rpy="0 0 0" />
    <parent
      link="left_hand_link" />
    <child
      link="left_hand_mid_bend_link" />
    <axis
      xyz="1 0 0" />
    <limit
      lower="-0.785"
      upper="0.262"
      effort="0.295"
      velocity="2" />
    <dynamics
      damping="0"
      friction="0" />
  </joint>
  <link
    name="left_hand_mid_rota_link1">
    <inertial>
      <origin
        xyz="-0.00460077435769424 2.64968949433009E-06 0.0165208271617643"
        rpy="0 0 0" />
      <mass
        value="0.07903209" />
      <inertia
        ixx="0.00001597"
        ixy="-0.00000011"
        ixz="-0.00000056"
        iyy="0.00001854"
        iyz="-0.00000003"
        izz="0.00000598" />
    </inertial>
    <visual>
      <origin
        xyz="0 0 0"
        rpy="0 0 0" />
      <geometry>
        <mesh
          filename="package://xhand_left/meshes/left_hand_mid_rota_link1.STL" />
      </geometry>
      <material
        name="">
        <color
          rgba="0.055 0.055 0.063 1" />
      </material>
    </visual>
    <collision>
      <origin
        xyz="0 0 0"
        rpy="0 0 0" />
      <geometry>
        <mesh
          filename="package://xhand_left/meshes/left_hand_mid_rota_link1.STL" />
      </geometry>
    </collision>
  </link>
  <joint
    name="left_hand_mid_rota_joint1"
    type="revolute">
    <origin
      xyz="0.0055 0 0.0233"
      rpy="0 0 0" />
    <parent
      link="left_hand_mid_bend_link" />
    <child
      link="left_hand_mid_rota_link1" />
    <axis
      xyz="0 1 0" />
    <limit
      lower="0"
      upper="1.571"
      effort="0.884"
      velocity="1.696" />
    <dynamics
      damping="0"
      friction="0" />
  </joint>
  <link
    name="left_hand_mid_rotaback_link1">
    <inertial>
      <origin
        xyz="-0.0199604212773734 -1.11555281569198E-06 -0.0153905493817256"
        rpy="0 0 0" />
      <mass
        value="0.001" />
      <inertia
        ixx="1e-8"
        ixy="0"
        ixz="0"
        iyy="1e-8"
        iyz="0"
        izz="1e-8" />
    </inertial>
    <visual>
      <origin
        xyz="0 0 0"
        rpy="0 0 0" />
      <geometry>
        <mesh
          filename="package://xhand_left/meshes/left_hand_mid_rotaback_link1.STL" />
      </geometry>
      <material
        name="">
        <color
          rgba="0.941 0.941 0.941 1" />
      </material>
    </visual>
    <collision>
      <origin
        xyz="0 0 0"
        rpy="0 0 0" />
      <geometry>
        <mesh
          filename="package://xhand_left/meshes/left_hand_mid_rotaback_link1.STL" />
      </geometry>
    </collision>
  </link>
  <joint
    name="left_hand_mid_rotaback_joint1"
    type="fixed">
    <origin
      xyz="0 0 0.0345"
      rpy="0 0 0" />
    <parent
      link="left_hand_mid_rota_link1" />
    <child
      link="left_hand_mid_rotaback_link1" />
    <axis
      xyz="0 0 0" />
    <dynamics
      damping="0"
      friction="0" />
  </joint>
  <link
    name="left_hand_mid_rota_link2">
    <inertial>
      <origin
        xyz="-0.00361835921106856 3.42637358226403E-05 0.0221934730898917"
        rpy="0 0 0" />
      <mass
        value="0.03780633" />
      <inertia
        ixx="0.00000528"
        ixy="0.00000001"
        ixz="0.00000013"
        iyy="0.00000557"
        iyz="0.00000005"
        izz="0.00000187" />
    </inertial>
    <visual>
      <origin
        xyz="0 0 0"
        rpy="0 0 0" />
      <geometry>
        <mesh
          filename="package://xhand_left/meshes/left_hand_mid_rota_link2.STL" />
      </geometry>
      <material
        name="">
        <color
          rgba="0.055 0.055 0.063 1" />
      </material>
    </visual>
    <collision>
      <origin
        xyz="0 0 0"
        rpy="0 0 0" />
      <geometry>
        <mesh
          filename="package://xhand_left/meshes/left_hand_mid_rota_link2.STL" />
      </geometry>
    </collision>
  </link>
  <joint
    name="left_hand_mid_rota_joint2"
    type="revolute">
    <origin
      xyz="0 0 0.0345"
      rpy="0 0 0" />
    <parent
      link="left_hand_mid_rota_link1" />
    <child
      link="left_hand_mid_rota_link2" />
    <axis
      xyz="0 1 0" />
    <limit
      lower="0"
      upper="1.571"
      effort="0.302"
      velocity="1.98" />
    <dynamics
      damping="0"
      friction="0" />
  </joint>
  <link
    name="left_hand_mid_rotaback_link2">
    <inertial>
      <origin
        xyz="-0.0111115553890412 -3.2718434207905E-05 -0.0136070034257485"
        rpy="0 0 0" />
      <mass
        value="0.001" />
      <inertia
        ixx="1e-8"
        ixy="0"
        ixz="0"
        iyy="1e-8"
        iyz="0"
        izz="1e-8" />
    </inertial>
    <visual>
      <origin
        xyz="0 0 0"
        rpy="0 0 0" />
      <geometry>
        <mesh
          filename="package://xhand_left/meshes/left_hand_mid_rotaback_link2.STL" />
      </geometry>
      <material
        name="">
        <color
          rgba="0.941 0.941 0.941 1" />
      </material>
    </visual>
    <collision>
      <origin
        xyz="0 0 0"
        rpy="0 0 0" />
      <geometry>
        <mesh
          filename="package://xhand_left/meshes/left_hand_mid_rotaback_link2.STL" />
      </geometry>
    </collision>
  </link>
  <joint
    name="left_hand_mid_rotaback_joint2"
    type="fixed">
    <origin
      xyz="-0.00450000000002273 0 0.0374168958538635"
      rpy="0 0 0" />
    <parent
      link="left_hand_mid_rota_link2" />
    <child
      link="left_hand_mid_rotaback_link2" />
    <axis
      xyz="0 0 0" />
    <dynamics
      damping="0"
      friction="0" />
  </joint>
  <link
    name="left_hand_mid_rota_link3">
    <inertial>
      <origin
        xyz="-0.00042616918427528 2.78792842317403E-06 0.0156390605202348"
        rpy="0 0 0" />
      <mass
        value="0.00650707" />
      <inertia
        ixx="0.00000052"
        ixy="0.0"
        ixz="0.00000002"
        iyy="0.00000049"
        iyz="-0.00000001"
        izz="0.00000025" />
    </inertial>
    <visual>
      <origin
        xyz="0 0 0"
        rpy="0 0 0" />
      <geometry>
        <mesh
          filename="package://xhand_left/meshes/left_hand_mid_rota_link3.STL" />
      </geometry>
      <material
        name="">
        <color
          rgba="0.055 0.055 0.063 1" />
      </material>
    </visual>
    <collision>
      <origin
        xyz="0 0 0"
        rpy="0 0 0" />
      <geometry>
        <mesh
          filename="package://xhand_left/meshes/left_hand_mid_rota_link3.STL" />
      </geometry>
    </collision>
  </link>
  <joint
    name="left_hand_mid_rota_joint3"
    type="revolute">
    <origin
      xyz="-0.0045 0 0.037417"
      rpy="0 0 0" />
    <parent
      link="left_hand_mid_rota_link2" />
    <child
      link="left_hand_mid_rota_link3" />
    <axis
      xyz="0 1 0" />
    <limit
      lower="0"
      upper="1.571"
      effort="0.295"
      velocity="2" />
    <dynamics
      damping="0"
      friction="0" />
  </joint>
  <link
    name="left_hand_mid_rota_link4">
    <inertial>
      <origin
        xyz="1.35134958778593E-15 -2.47996068125644E-14 8.32667268468867E-17"
        rpy="0 0 0" />
      <mass
        value="0.001" />
      <inertia
        ixx="1e-8"
        ixy="0"
        ixz="0"
        iyy="1e-8"
        iyz="0"
        izz="1e-8" />
    </inertial>
    <visual>
      <origin
        xyz="0 0 0"
        rpy="0 0 0" />
      <geometry>
        <mesh
          filename="package://xhand_left/meshes/left_hand_mid_rota_link4.STL" />
      </geometry>
      <material
        name="">
        <color
          rgba="0.055 0.055 0.063 1" />
      </material>
    </visual>
    <collision>
      <origin
        xyz="0 0 0"
        rpy="0 0 0" />
      <geometry>
        <mesh
          filename="package://xhand_left/meshes/left_hand_mid_rota_link4.STL" />
      </geometry>
    </collision>
  </link>
  <joint
    name="left_hand_mid_rota_joint4"
    type="fixed">
    <origin
      xyz="0.00791114210911789 0 0.0181728187018944"
      rpy="0 0 0" />
    <parent
      link="left_hand_mid_rota_link3" />
    <child
      link="left_hand_mid_rota_link4" />
    <axis
      xyz="0 0 0" />
    <dynamics
      damping="0"
      friction="0" />
  </joint>
  <link
    name="left_hand_mid_rota_link5">
    <inertial>
      <origin
        xyz="1.34354333214404E-15 -2.48273623881801E-14 8.32667268468867E-17"
        rpy="0 0 0" />
      <mass
        value="0.001" />
      <inertia
        ixx="1e-8"
        ixy="0"
        ixz="0"
        iyy="1e-8"
        iyz="0"
        izz="1e-8" />
    </inertial>
    <visual>
      <origin
        xyz="0 0 0"
        rpy="0 0 0" />
      <geometry>
        <mesh
          filename="package://xhand_left/meshes/left_hand_mid_rota_link5.STL" />
      </geometry>
      <material
        name="">
        <color
          rgba="0.055 0.055 0.063 1" />
      </material>
    </visual>
    <collision>
      <origin
        xyz="0 0 0"
        rpy="0 0 0" />
      <geometry>
        <mesh
          filename="package://xhand_left/meshes/left_hand_mid_rota_link5.STL" />
      </geometry>
    </collision>
  </link>
  <joint
    name="left_hand_mid_rota_joint5"
    type="fixed">
    <origin
      xyz="0 0 0.0312512504715663"
      rpy="0 0 0" />
    <parent
      link="left_hand_mid_rota_link3" />
    <child
      link="left_hand_mid_rota_link5" />
    <axis
      xyz="0 0 0" />
    <dynamics
      damping="0"
      friction="0" />
  </joint>
  <link
    name="left_hand_ring_bend_link">
    <inertial>
      <origin
        xyz="0.000800179555044945 -1.22991894446756E-15 0.0116298859000074"
        rpy="0 0 0" />
      <mass
        value="0.00581743" />
      <inertia
        ixx="0.00000043"
        ixy="0.0"
        ixz="-0.00000004"
        iyy="0.00000042"
        iyz="0.00000001"
        izz="0.00000032" />
    </inertial>
    <visual>
      <origin
        xyz="0 0 0"
        rpy="0 0 0" />
      <geometry>
        <mesh
          filename="package://xhand_left/meshes/left_hand_ring_bend_link.STL" />
      </geometry>
      <material
        name="">
        <color
          rgba="0.055 0.055 0.063 1" />
      </material>
    </visual>
    <collision>
      <origin
        xyz="0 0 0"
        rpy="0 0 0" />
      <geometry>
        <mesh
          filename="package://xhand_left/meshes/left_hand_ring_bend_link.STL" />
      </geometry>
    </collision>
  </link>
  <joint
    name="left_hand_ring_bend_joint"
    type="revolute">
    <origin
      xyz="0.0045 0.014087 0.094293"
      rpy="0 0 0" />
    <parent
      link="left_hand_link" />
    <child
      link="left_hand_ring_bend_link" />
    <axis
      xyz="1 0 0" />
    <limit
      lower="-0.785"
      upper="0.262"
      effort="0.295"
      velocity="2" />
    <dynamics
      damping="0"
      friction="0" />
  </joint>
  <link
    name="left_hand_ring_rota_link1">
    <inertial>
      <origin
        xyz="-0.00460077125786092 2.64797400240623E-06 0.0165208296430851"
        rpy="0 0 0" />
      <mass
        value="0.07903209" />
      <inertia
        ixx="0.00001597"
        ixy="-0.00000011"
        ixz="-0.00000056"
        iyy="0.00001854"
        iyz="-0.00000003"
        izz="0.00000598" />
    </inertial>
    <visual>
      <origin
        xyz="0 0 0"
        rpy="0 0 0" />
      <geometry>
        <mesh
          filename="package://xhand_left/meshes/left_hand_ring_rota_link1.STL" />
      </geometry>
      <material
        name="">
        <color
          rgba="0.055 0.055 0.063 1" />
      </material>
    </visual>
    <collision>
      <origin
        xyz="0 0 0"
        rpy="0 0 0" />
      <geometry>
        <mesh
          filename="package://xhand_left/meshes/left_hand_ring_rota_link1.STL" />
      </geometry>
    </collision>
  </link>
  <joint
    name="left_hand_ring_rota_joint1"
    type="revolute">
    <origin
      xyz="0.0055 0 0.0233"
      rpy="0 0 0" />
    <parent
      link="left_hand_ring_bend_link" />
    <child
      link="left_hand_ring_rota_link1" />
    <axis
      xyz="0 1 0" />
    <limit
      lower="0"
      upper="1.571"
      effort="0.884"
      velocity="1.696" />
    <dynamics
      damping="0"
      friction="0" />
  </joint>
  <link
    name="left_hand_ring_rotaback_link1">
    <inertial>
      <origin
        xyz="-0.0199604212773755 -1.11555281080179E-06 -0.0153905493817846"
        rpy="0 0 0" />
      <mass
        value="0.001" />
      <inertia
        ixx="1e-8"
        ixy="0"
        ixz="0"
        iyy="1e-8"
        iyz="0"
        izz="1e-8" />
    </inertial>
    <visual>
      <origin
        xyz="0 0 0"
        rpy="0 0 0" />
      <geometry>
        <mesh
          filename="package://xhand_left/meshes/left_hand_ring_rotaback_link1.STL" />
      </geometry>
      <material
        name="">
        <color
          rgba="0.941 0.941 0.941 1" />
      </material>
    </visual>
    <collision>
      <origin
        xyz="0 0 0"
        rpy="0 0 0" />
      <geometry>
        <mesh
          filename="package://xhand_left/meshes/left_hand_ring_rotaback_link1.STL" />
      </geometry>
    </collision>
  </link>
  <joint
    name="left_hand_ring_rotaback_joint1"
    type="fixed">
    <origin
      xyz="0 0 0.0345"
      rpy="0 0 0" />
    <parent
      link="left_hand_ring_rota_link1" />
    <child
      link="left_hand_ring_rotaback_link1" />
    <axis
      xyz="0 0 0" />
    <dynamics
      damping="0"
      friction="0" />
  </joint>
  <link
    name="left_hand_ring_rota_link2">
    <inertial>
      <origin
        xyz="-0.00361835935628366 3.42636253831564E-05 0.0221934729736574"
        rpy="0 0 0" />
      <mass
        value="0.03780633" />
      <inertia
        ixx="0.00000528"
        ixy="0.00000001"
        ixz="0.00000013"
        iyy="0.00000557"
        iyz="0.00000005"
        izz="0.00000187" />
    </inertial>
    <visual>
      <origin
        xyz="0 0 0"
        rpy="0 0 0" />
      <geometry>
        <mesh
          filename="package://xhand_left/meshes/left_hand_ring_rota_link2.STL" />
      </geometry>
      <material
        name="">
        <color
          rgba="0.055 0.055 0.063 1" />
      </material>
    </visual>
    <collision>
      <origin
        xyz="0 0 0"
        rpy="0 0 0" />
      <geometry>
        <mesh
          filename="package://xhand_left/meshes/left_hand_ring_rota_link2.STL" />
      </geometry>
    </collision>
  </link>
  <joint
    name="left_hand_ring_rota_joint2"
    type="revolute">
    <origin
      xyz="0 0 0.0345"
      rpy="0 0 0" />
    <parent
      link="left_hand_ring_rota_link1" />
    <child
      link="left_hand_ring_rota_link2" />
    <axis
      xyz="0 1 0" />
    <limit
      lower="0"
      upper="1.571"
      effort="0.302"
      velocity="1.98" />
    <dynamics
      damping="0"
      friction="0" />
  </joint>
  <link
    name="left_hand_ring_rotaback_link2">
    <inertial>
      <origin
        xyz="-0.0111115556264864 -3.27152099488595E-05 -0.0136070012078522"
        rpy="0 0 0" />
      <mass
        value="0.001" />
      <inertia
        ixx="1e-8"
        ixy="0"
        ixz="0"
        iyy="1e-8"
        iyz="0"
        izz="1e-8" />
    </inertial>
    <visual>
      <origin
        xyz="0 0 0"
        rpy="0 0 0" />
      <geometry>
        <mesh
          filename="package://xhand_left/meshes/left_hand_ring_rotaback_link2.STL" />
      </geometry>
      <material
        name="">
        <color
          rgba="0.941 0.941 0.941 1" />
      </material>
    </visual>
    <collision>
      <origin
        xyz="0 0 0"
        rpy="0 0 0" />
      <geometry>
        <mesh
          filename="package://xhand_left/meshes/left_hand_ring_rotaback_link2.STL" />
      </geometry>
    </collision>
  </link>
  <joint
    name="left_hand_ring_rotaback_joint2"
    type="fixed">
    <origin
      xyz="-0.00450000000002274 0 0.0374168958538635"
      rpy="0 0 0" />
    <parent
      link="left_hand_ring_rota_link2" />
    <child
      link="left_hand_ring_rotaback_link2" />
    <axis
      xyz="0 0 0" />
    <dynamics
      damping="0"
      friction="0" />
  </joint>
  <link
    name="left_hand_ring_rota_link3">
    <inertial>
      <origin
        xyz="-0.000426169589995764 2.78668873688465E-06 0.0156390621706919"
        rpy="0 0 0" />
      <mass
        value="0.00650707" />
      <inertia
        ixx="0.00000052"
        ixy="0.0"
        ixz="0.00000002"
        iyy="0.00000049"
        iyz="-0.00000001"
        izz="0.00000025" />
    </inertial>
    <visual>
      <origin
        xyz="0 0 0"
        rpy="0 0 0" />
      <geometry>
        <mesh
          filename="package://xhand_left/meshes/left_hand_ring_rota_link3.STL" />
      </geometry>
      <material
        name="">
        <color
          rgba="0.055 0.055 0.063 1" />
      </material>
    </visual>
    <collision>
      <origin
        xyz="0 0 0"
        rpy="0 0 0" />
      <geometry>
        <mesh
          filename="package://xhand_left/meshes/left_hand_ring_rota_link3.STL" />
      </geometry>
    </collision>
  </link>
  <joint
    name="left_hand_ring_rota_joint3"
    type="revolute">
    <origin
      xyz="-0.0045 0 0.037417"
      rpy="0 0 0" />
    <parent
      link="left_hand_ring_rota_link2" />
    <child
      link="left_hand_ring_rota_link3" />
    <axis
      xyz="0 1 0" />
    <limit
      lower="0"
      upper="1.571"
      effort="0.295"
      velocity="2" />
    <dynamics
      damping="0"
      friction="0" />
  </joint>
  <link
    name="left_hand_ring_rota_link4">
    <inertial>
      <origin
        xyz="1.31492039479042E-15 -2.46955234040058E-14 2.77555756156289E-17"
        rpy="0 0 0" />
      <mass
        value="0.001" />
      <inertia
        ixx="1e-8"
        ixy="0"
        ixz="0"
        iyy="1e-8"
        iyz="0"
        izz="1e-8" />
    </inertial>
    <visual>
      <origin
        xyz="0 0 0"
        rpy="0 0 0" />
      <geometry>
        <mesh
          filename="package://xhand_left/meshes/left_hand_ring_rota_link4.STL" />
      </geometry>
      <material
        name="">
        <color
          rgba="0.055 0.055 0.063 1" />
      </material>
    </visual>
    <collision>
      <origin
        xyz="0 0 0"
        rpy="0 0 0" />
      <geometry>
        <mesh
          filename="package://xhand_left/meshes/left_hand_ring_rota_link4.STL" />
      </geometry>
    </collision>
  </link>
  <joint
    name="left_hand_ring_rota_joint4"
    type="fixed">
    <origin
      xyz="0.00791114210911523 0 0.0181728187018944"
      rpy="0 0 0" />
    <parent
      link="left_hand_ring_rota_link3" />
    <child
      link="left_hand_ring_rota_link4" />
    <axis
      xyz="0 0 0" />
    <dynamics
      damping="0"
      friction="0" />
  </joint>
  <link
    name="left_hand_ring_rota_link5">
    <inertial>
      <origin
        xyz="1.32099192695634E-15 -2.47163400857175E-14 2.77555756156289E-17"
        rpy="0 0 0" />
      <mass
        value="0.001" />
      <inertia
        ixx="1e-8"
        ixy="0"
        ixz="0"
        iyy="1e-8"
        iyz="0"
        izz="1e-8" />
    </inertial>
    <visual>
      <origin
        xyz="0 0 0"
        rpy="0 0 0" />
      <geometry>
        <mesh
          filename="package://xhand_left/meshes/left_hand_ring_rota_link5.STL" />
      </geometry>
      <material
        name="">
        <color
          rgba="0.055 0.055 0.063 1" />
      </material>
    </visual>
    <collision>
      <origin
        xyz="0 0 0"
        rpy="0 0 0" />
      <geometry>
        <mesh
          filename="package://xhand_left/meshes/left_hand_ring_rota_link5.STL" />
      </geometry>
    </collision>
  </link>
  <joint
    name="left_hand_ring_rota_joint5"
    type="fixed">
    <origin
      xyz="0 0 0.0312512504715663"
      rpy="0 0 0" />
    <parent
      link="left_hand_ring_rota_link3" />
    <child
      link="left_hand_ring_rota_link5" />
    <axis
      xyz="0 0 0" />
    <dynamics
      damping="0"
      friction="0" />
  </joint>
  <link
    name="left_hand_ltspalm_link">
    <inertial>
      <origin
        xyz="-0.00282724296722215 0.010875275522686 0.0259189752413506"
        rpy="0 0 0" />
      <mass
        value="0.07212035" />
      <inertia
        ixx="0.00002472"
        ixy="-0.00000013"
        ixz="0.00000264"
        iyy="0.00002557"
        iyz="-0.00000053"
        izz="0.00000658" />
    </inertial>
    <visual>
      <origin
        xyz="0 0 0"
        rpy="0 0 0" />
      <geometry>
        <mesh
          filename="package://xhand_left/meshes/left_hand_ltspalm_link.STL" />
      </geometry>
      <material
        name="">
        <color
          rgba="0.055 0.055 0.063 1" />
      </material>
    </visual>
    <collision>
      <origin
        xyz="0 0 0"
        rpy="0 0 0" />
      <geometry>
        <mesh
          filename="package://xhand_left/meshes/left_hand_ltspalm_link.STL" />
      </geometry>
    </collision>
  </link>
  <joint
    name="left_hand_ltspalm_joint"
    type="revolute">
    <origin
      xyz="0.0115 0.0265 0.041"
      rpy="0 0 0" />
    <parent
      link="left_hand_link" />
    <child
      link="left_hand_ltspalm_link" />
    <axis
      xyz="0 0 -1" />
    <limit
      lower="0"
      upper="0.524"
      effort="0.295"
      velocity="2" />
    <dynamics
      damping="0"
      friction="0" />
  </joint>
  <link
    name="left_hand_ltsdorsum_link">
    <inertial>
      <origin
        xyz="-0.0138513128735783 0.0110945164536879 0.0132761044356019"
        rpy="0 0 0" />
      <mass
        value="0.001" />
      <inertia
        ixx="1e-8"
        ixy="0"
        ixz="0"
        iyy="1e-8"
        iyz="0"
        izz="1e-8" />
    </inertial>
    <visual>
      <origin
        xyz="0 0 0"
        rpy="0 0 0" />
      <geometry>
        <mesh
          filename="package://xhand_left/meshes/left_hand_ltsdorsum_link.STL" />
      </geometry>
      <material
        name="">
        <color
          rgba="0.941 0.941 0.941 1" />
      </material>
    </visual>
    <collision>
      <origin
        xyz="0 0 0"
        rpy="0 0 0" />
      <geometry>
        <mesh
          filename="package://xhand_left/meshes/left_hand_ltsdorsum_link.STL" />
      </geometry>
    </collision>
  </link>
  <joint
    name="left_hand_ltsdorsum_joint"
    type="fixed">
    <origin
      xyz="0 0 0"
      rpy="0 0 0" />
    <parent
      link="left_hand_ltspalm_link" />
    <child
      link="left_hand_ltsdorsum_link" />
    <axis
      xyz="0 0 0" />
    <dynamics
      damping="0"
      friction="0" />
  </joint>
  <link
    name="left_hand_pinky_bend_link">
    <inertial>
      <origin
        xyz="0.000800179555050164 -1.22818422099158E-15 0.0116298859000021"
        rpy="0 0 0" />
      <mass
        value="0.00581743" />
      <inertia
        ixx="0.00000043"
        ixy="0.0"
        ixz="-0.00000004"
        iyy="0.00000042"
        iyz="0.00000001"
        izz="0.00000032" />
    </inertial>
    <visual>
      <origin
        xyz="0 0 0"
        rpy="0 0 0" />
      <geometry>
        <mesh
          filename="package://xhand_left/meshes/left_hand_pinky_bend_link.STL" />
      </geometry>
      <material
        name="">
        <color
          rgba="0.055 0.055 0.063 1" />
      </material>
    </visual>
    <collision>
      <origin
        xyz="0 0 0"
        rpy="0 0 0" />
      <geometry>
        <mesh
          filename="package://xhand_left/meshes/left_hand_pinky_bend_link.STL" />
      </geometry>
    </collision>
  </link>
  <joint
    name="left_hand_pinky_bend_joint"
    type="revolute">
    <origin
      xyz="-0.007 0.011478 0.044292"
      rpy="0 0 0" />
    <parent
      link="left_hand_ltspalm_link" />
    <child
      link="left_hand_pinky_bend_link" />
    <axis
      xyz="1 0 0" />
    <limit
      lower="-1.047"
      upper="0.175"
      effort="0.295"
      velocity="2" />
    <dynamics
      damping="0"
      friction="0" />
  </joint>
  <link
    name="left_hand_pinky_rota_link1">
    <inertial>
      <origin
        xyz="-0.00460077435054488 2.64949028256495E-06 0.0165208272953632"
        rpy="0 0 0" />
      <mass
        value="0.07903209" />
      <inertia
        ixx="0.00001597"
        ixy="-0.00000011"
        ixz="-0.00000056"
        iyy="0.00001854"
        iyz="-0.00000003"
        izz="0.00000598" />
    </inertial>
    <visual>
      <origin
        xyz="0 0 0"
        rpy="0 0 0" />
      <geometry>
        <mesh
          filename="package://xhand_left/meshes/left_hand_pinky_rota_link1.STL" />
      </geometry>
      <material
        name="">
        <color
          rgba="0.055 0.055 0.063 1" />
      </material>
    </visual>
    <collision>
      <origin
        xyz="0 0 0"
        rpy="0 0 0" />
      <geometry>
        <mesh
          filename="package://xhand_left/meshes/left_hand_pinky_rota_link1.STL" />
      </geometry>
    </collision>
  </link>
  <joint
    name="left_hand_pinky_rota_joint1"
    type="revolute">
    <origin
      xyz="0.0055 0 0.0233"
      rpy="0 0 0" />
    <parent
      link="left_hand_pinky_bend_link" />
    <child
      link="left_hand_pinky_rota_link1" />
    <axis
      xyz="0 1 0" />
    <limit
      lower="0"
      upper="1.571"
      effort="0.884"
      velocity="1.696" />
    <dynamics
      damping="0"
      friction="0" />
  </joint>
  <link
    name="left_hand_pinky_rotaback_link1">
    <inertial>
      <origin
        xyz="-0.0199604212773855 -1.11555280015579E-06 -0.0153905493817869"
        rpy="0 0 0" />
      <mass
        value="0.001" />
      <inertia
        ixx="1e-8"
        ixy="0"
        ixz="0"
        iyy="1e-8"
        iyz="0"
        izz="1e-8" />
    </inertial>
    <visual>
      <origin
        xyz="0 0 0"
        rpy="0 0 0" />
      <geometry>
        <mesh
          filename="package://xhand_left/meshes/left_hand_pinky_rotaback_link1.STL" />
      </geometry>
      <material
        name="">
        <color
          rgba="0.941 0.941 0.941 1" />
      </material>
    </visual>
    <collision>
      <origin
        xyz="0 0 0"
        rpy="0 0 0" />
      <geometry>
        <mesh
          filename="package://xhand_left/meshes/left_hand_pinky_rotaback_link1.STL" />
      </geometry>
    </collision>
  </link>
  <joint
    name="left_hand_pinky_rotaback_joint1"
    type="fixed">
    <origin
      xyz="0 0 0.0345"
      rpy="0 0 0" />
    <parent
      link="left_hand_pinky_rota_link1" />
    <child
      link="left_hand_pinky_rotaback_link1" />
    <axis
      xyz="0 0 0" />
    <dynamics
      damping="0"
      friction="0" />
  </joint>
  <link
    name="left_hand_pinky_rota_link2">
    <inertial>
      <origin
        xyz="-0.00361835936094035 3.42636238934713E-05 0.0221934729734662"
        rpy="0 0 0" />
      <mass
        value="0.03780633" />
      <inertia
        ixx="0.00000528"
        ixy="0.00000001"
        ixz="0.00000013"
        iyy="0.00000557"
        iyz="0.00000005"
        izz="0.00000187" />
    </inertial>
    <visual>
      <origin
        xyz="0 0 0"
        rpy="0 0 0" />
      <geometry>
        <mesh
          filename="package://xhand_left/meshes/left_hand_pinky_rota_link2.STL" />
      </geometry>
      <material
        name="">
        <color
          rgba="0.055 0.055 0.063 1" />
      </material>
    </visual>
    <collision>
      <origin
        xyz="0 0 0"
        rpy="0 0 0" />
      <geometry>
        <mesh
          filename="package://xhand_left/meshes/left_hand_pinky_rota_link2.STL" />
      </geometry>
    </collision>
  </link>
  <joint
    name="left_hand_pinky_rota_joint2"
    type="revolute">
    <origin
      xyz="0 0 0.0345"
      rpy="0 0 0" />
    <parent
      link="left_hand_pinky_rota_link1" />
    <child
      link="left_hand_pinky_rota_link2" />
    <axis
      xyz="0 1 0" />
    <limit
      lower="0"
      upper="1.571"
      effort="0.302"
      velocity="1.98" />
    <dynamics
      damping="0"
      friction="0" />
  </joint>
  <link
    name="left_hand_pinky_rotaback_link2">
    <inertial>
      <origin
        xyz="-0.0111115562722129 -3.27171759701567E-05 -0.0136070041651558"
        rpy="0 0 0" />
      <mass
        value="0.001" />
      <inertia
        ixx="1e-8"
        ixy="0"
        ixz="0"
        iyy="1e-8"
        iyz="0"
        izz="1e-8" />
    </inertial>
    <visual>
      <origin
        xyz="0 0 0"
        rpy="0 0 0" />
      <geometry>
        <mesh
          filename="package://xhand_left/meshes/left_hand_pinky_rotaback_link2.STL" />
      </geometry>
      <material
        name="">
        <color
          rgba="0.941 0.941 0.941 1" />
      </material>
    </visual>
    <collision>
      <origin
        xyz="0 0 0"
        rpy="0 0 0" />
      <geometry>
        <mesh
          filename="package://xhand_left/meshes/left_hand_pinky_rotaback_link2.STL" />
      </geometry>
    </collision>
  </link>
  <joint
    name="left_hand_pinky_rotaback_joint2"
    type="fixed">
    <origin
      xyz="-0.00450000000000014 0 0.0374168958538662"
      rpy="0 0 0" />
    <parent
      link="left_hand_pinky_rota_link2" />
    <child
      link="left_hand_pinky_rotaback_link2" />
    <axis
      xyz="0 0 0" />
    <dynamics
      damping="0"
      friction="0" />
  </joint>
  <link
    name="left_hand_pinky_rota_link3">
    <inertial>
      <origin
        xyz="-0.000426169793810456 2.7867883233626E-06 0.0156390627800144"
        rpy="0 0 0" />
      <mass
        value="0.00650707" />
      <inertia
        ixx="0.00000052"
        ixy="0.0"
        ixz="0.00000002"
        iyy="0.00000049"
        iyz="-0.00000001"
        izz="0.00000025" />
    </inertial>
    <visual>
      <origin
        xyz="0 0 0"
        rpy="0 0 0" />
      <geometry>
        <mesh
          filename="package://xhand_left/meshes/left_hand_pinky_rota_link3.STL" />
      </geometry>
      <material
        name="">
        <color
          rgba="0.055 0.055 0.063 1" />
      </material>
    </visual>
    <collision>
      <origin
        xyz="0 0 0"
        rpy="0 0 0" />
      <geometry>
        <mesh
          filename="package://xhand_left/meshes/left_hand_pinky_rota_link3.STL" />
      </geometry>
    </collision>
  </link>
  <joint
    name="left_hand_pinky_rota_joint3"
    type="revolute">
    <origin
      xyz="-0.0045 0 0.037417"
      rpy="0 0 0" />
    <parent
      link="left_hand_pinky_rota_link2" />
    <child
      link="left_hand_pinky_rota_link3" />
    <axis
      xyz="0 1 0" />
    <limit
      lower="0"
      upper="1.571"
      effort="0.295"
      velocity="2" />
    <dynamics
      damping="0"
      friction="0" />
  </joint>
  <link
    name="left_hand_pinky_rota_link4">
    <inertial>
      <origin
        xyz="0 -2.47996068125644E-14 2.77555756156289E-17"
        rpy="0 0 0" />
      <mass
        value="0.001" />
      <inertia
        ixx="1e-8"
        ixy="0"
        ixz="0"
        iyy="1e-8"
        iyz="0"
        izz="1e-8" />
    </inertial>
    <visual>
      <origin
        xyz="0 0 0"
        rpy="0 0 0" />
      <geometry>
        <mesh
          filename="package://xhand_left/meshes/left_hand_pinky_rota_link4.STL" />
      </geometry>
      <material
        name="">
        <color
          rgba="0.055 0.055 0.063 1" />
      </material>
    </visual>
    <collision>
      <origin
        xyz="0 0 0"
        rpy="0 0 0" />
      <geometry>
        <mesh
          filename="package://xhand_left/meshes/left_hand_pinky_rota_link4.STL" />
      </geometry>
    </collision>
  </link>
  <joint
    name="left_hand_pinky_rota_joint4"
    type="fixed">
    <origin
      xyz="0.00791114210900066 0 0.0181728187018977"
      rpy="0 0 0" />
    <parent
      link="left_hand_pinky_rota_link3" />
    <child
      link="left_hand_pinky_rota_link4" />
    <axis
      xyz="0 0 0" />
    <dynamics
      damping="0"
      friction="0" />
  </joint>
  <link
    name="left_hand_pinky_rota_link5">
    <inertial>
      <origin
        xyz="0 -2.48273623881801E-14 2.77555756156289E-17"
        rpy="0 0 0" />
      <mass
        value="0.001" />
      <inertia
        ixx="1e-8"
        ixy="0"
        ixz="0"
        iyy="1e-8"
        iyz="0"
        izz="1e-8" />
    </inertial>
    <visual>
      <origin
        xyz="0 0 0"
        rpy="0 0 0" />
      <geometry>
        <mesh
          filename="package://xhand_left/meshes/left_hand_pinky_rota_link5.STL" />
      </geometry>
      <material
        name="">
        <color
          rgba="0.055 0.055 0.063 1" />
      </material>
    </visual>
    <collision>
      <origin
        xyz="0 0 0"
        rpy="0 0 0" />
      <geometry>
        <mesh
          filename="package://xhand_left/meshes/left_hand_pinky_rota_link5.STL" />
      </geometry>
    </collision>
  </link>
  <joint
    name="left_hand_pinky_rota_joint5"
    type="fixed">
    <origin
      xyz="0 0 0.0312512504715696"
      rpy="0 0 0" />
    <parent
      link="left_hand_pinky_rota_link3" />
    <child
      link="left_hand_pinky_rota_link5" />
    <axis
      xyz="0 0 0" />
    <dynamics
      damping="0"
      friction="0" />
  </joint>
</robot>