<?xml version='1.0' encoding='utf-8'?>
<robot name="xarm7_xhand1pro_right"><link name="link_base">
    <inertial>
      <origin rpy="0 0 0" xyz="-0.021131 -0.0016302 0.056488" />
      <mass value="0.88556" />
      <inertia ixx="0.0030595" ixy="0.00012259" ixz="-0.00062705" iyy="0.0037783" iyz="0.00027023" izz="0.0020125" />
    </inertial>
    <visual>
      <geometry>
        <mesh filename="../xarm7/meshes/visual/link_base.glb" />
      </geometry>
      <origin rpy="0 0 0" xyz="0 0 0" />
    </visual>
    <collision>
      <geometry>
        <mesh filename="../xarm7/meshes/collision/link_base.obj" />
      </geometry>
      <origin rpy="0 0 0" xyz="0 0 0" />
    </collision>
  </link><link name="link1">
    <inertial>
      <origin rpy="0 0 0" xyz="-0.0002 0.02905 -0.01233" />
      <mass value="2.382" />
      <inertia ixx="0.0056905" ixy="-1.579e-05" ixz="5.125e-06" iyy="0.0049566" iyz="-0.000873378" izz="0.003316654" />
    </inertial>
    <visual>
      <geometry>
        <mesh filename="../xarm7/meshes/visual/link1.glb" />
      </geometry>
      <origin rpy="0 0 0" xyz="0 0 0" />
    </visual>
    <collision>
      <geometry>
        <mesh filename="../xarm7/meshes/collision/link1.obj" />
      </geometry>
      <origin rpy="0 0 0" xyz="0 0 0" />
    </collision>
  </link><joint name="joint1" type="revolute">
    <origin rpy="0 0 0" xyz="0 0 0.267" />
    <parent link="link_base" />
    <child link="link1" />
    <axis xyz="0 0 1" />
    <limit effort="50" lower="-6.28318530718" upper="6.28318530718" velocity="3.14" />
    <dynamics damping="10" friction="1" />
  </joint><link name="link2">
    <inertial>
      <origin rpy="0 0 0" xyz="0.00022 -0.12856 0.01735" />
      <mass value="1.869" />
      <inertia ixx="0.0095989" ixy="1.541e-06" ixz="5.56e-06" iyy="0.00382472" iyz="-0.00317156" izz="0.007565669" />
    </inertial>
    <visual>
      <geometry>
        <mesh filename="../xarm7/meshes/visual/link2.glb" />
      </geometry>
      <origin rpy="0 0 0" xyz="0 0 0" />
    </visual>
    <collision>
      <geometry>
        <mesh filename="../xarm7/meshes/collision/link2.obj" />
      </geometry>
      <origin rpy="0 0 0" xyz="0 0 0" />
    </collision>
  </link><joint name="joint2" type="revolute">
    <origin rpy="-1.5708 0 0" xyz="0 0 0" />
    <parent link="link1" />
    <child link="link2" />
    <axis xyz="0 0 1" />
    <limit effort="50" lower="-2.059" upper="2.0944" velocity="3.14" />
    <dynamics damping="10" friction="1" />
  </joint><link name="link3">
    <inertial>
      <origin rpy="0 0 0" xyz="0.0466 -0.02463 -0.00768" />
      <mass value="1.6383" />
      <inertia ixx="0.00310955" ixy="0.00030837" ixz="-0.00058453" iyy="0.00264483" iyz="0.000338893" izz="0.0026624" />
    </inertial>
    <visual>
      <geometry>
        <mesh filename="../xarm7/meshes/visual/link3.glb" />
      </geometry>
      <origin rpy="0 0 0" xyz="0 0 0" />
    </visual>
    <collision>
      <geometry>
        <mesh filename="../xarm7/meshes/collision/link3.obj" />
      </geometry>
      <origin rpy="0 0 0" xyz="0 0 0" />
    </collision>
  </link><joint name="joint3" type="revolute">
    <origin rpy="1.5708 0 0" xyz="0 -0.293 0" />
    <parent link="link2" />
    <child link="link3" />
    <axis xyz="0 0 1" />
    <limit effort="30" lower="-6.28318530718" upper="6.28318530718" velocity="3.14" />
    <dynamics damping="5" friction="1" />
  </joint><link name="link4">
    <inertial>
      <origin rpy="0 0 0" xyz="0.07047 -0.11575 0.012" />
      <mass value="1.7269" />
      <inertia ixx="0.005889" ixy="0.00137112" ixz="0.00088143" iyy="0.00359703" iyz="-0.001762155" izz="0.00543244" />
    </inertial>
    <visual>
      <geometry>
        <mesh filename="../xarm7/meshes/visual/link4.glb" />
      </geometry>
      <origin rpy="0 0 0" xyz="0 0 0" />
    </visual>
    <collision>
      <geometry>
        <mesh filename="../xarm7/meshes/collision/link4.obj" />
      </geometry>
      <origin rpy="0 0 0" xyz="0 0 0" />
    </collision>
  </link><joint name="joint4" type="revolute">
    <origin rpy="1.5708 0 0" xyz="0.0525 0 0" />
    <parent link="link3" />
    <child link="link4" />
    <axis xyz="0 0 1" />
    <limit effort="30" lower="-0.19198" upper="3.927" velocity="3.14" />
    <dynamics damping="5" friction="1" />
  </joint><link name="link5">
    <inertial>
      <origin rpy="0 0 0" xyz="-0.00032 0.01604 -0.026" />
      <mass value="1.3203" />
      <inertia ixx="0.00534665" ixy="1.5117e-05" ixz="-3.69e-07" iyy="0.0049779" iyz="-0.00022132" izz="0.0013624" />
    </inertial>
    <visual>
      <geometry>
        <mesh filename="../xarm7/meshes/visual/link5.glb" />
      </geometry>
      <origin rpy="0 0 0" xyz="0 0 0" />
    </visual>
    <collision>
      <geometry>
        <mesh filename="../xarm7/meshes/collision/link5.obj" />
      </geometry>
      <origin rpy="0 0 0" xyz="0 0 0" />
    </collision>
  </link><joint name="joint5" type="revolute">
    <origin rpy="1.5708 0 0" xyz="0.0775 -0.3425 0" />
    <parent link="link4" />
    <child link="link5" />
    <axis xyz="0 0 1" />
    <limit effort="30" lower="-6.28318530718" upper="6.28318530718" velocity="3.14" />
    <dynamics damping="5" friction="1" />
  </joint><link name="link6">
    <inertial>
      <origin rpy="0 0 0" xyz="0.06469 0.03278 0.02141" />
      <mass value="1.325" />
      <inertia ixx="0.0014745" ixy="-0.000488" ixz="0.0002953" iyy="0.0019037" iyz="0.00014749" izz="0.0023652" />
    </inertial>
    <visual>
      <geometry>
        <mesh filename="../xarm7/meshes/visual/link6.glb" />
      </geometry>
      <origin rpy="0 0 0" xyz="0 0 0" />
    </visual>
    <collision>
      <geometry>
        <mesh filename="../xarm7/meshes/collision/link6.obj" />
      </geometry>
      <origin rpy="0 0 0" xyz="0 0 0" />
    </collision>
  </link><joint name="joint6" type="revolute">
    <origin rpy="1.5708 0 0" xyz="0 0 0" />
    <parent link="link5" />
    <child link="link6" />
    <axis xyz="0 0 1" />
    <limit effort="20" lower="-1.69297" upper="3.14159265359" velocity="3.14" />
    <dynamics damping="2" friction="1" />
  </joint><link name="link7">
    <inertial>
      <origin rpy="0 0 0" xyz="0 -0.00677 -0.01098" />
      <mass value="0.17" />
      <inertia ixx="9.3e-05" ixy="-0.0" ixz="-0.0" iyy="5.87e-05" iyz="-3.6e-06" izz="0.000132" />
    </inertial>
    <visual>
      <geometry>
        <mesh filename="../xarm7/meshes/visual/link7.glb" />
      </geometry>
      <origin rpy="0 0 0" xyz="0 0 0" />
    </visual>
    <collision>
      <geometry>
        <mesh filename="../xarm7/meshes/collision/link7.obj" />
      </geometry>
      <origin rpy="0 0 0" xyz="0 0 0" />
    </collision>
  </link><joint name="joint7" type="revolute">
    <origin rpy="-1.5708 0 0" xyz="0.076 0.097 0" />
    <parent link="link6" />
    <child link="link7" />
    <axis xyz="0 0 1" />
    <limit effort="20" lower="-6.28318530718" upper="6.28318530718" velocity="3.14" />
    <dynamics damping="2" friction="1" />
  </joint><joint name="joint_eef" type="fixed"><origin rpy="0 0 0" xyz="0 0 0" /><parent link="link7" /><child link="right_hand_link" /></joint><link name="right_hand_link">
    <inertial>
      <origin xyz="-0.00262279334965249 1.46813910362051E-07 0.0149884055957892" rpy="0 0 0" />
      <mass value="0.45051794" />
      <inertia ixx="0.00056226" ixy="-0.00001166" ixz="-0.00000198" iyy="0.0004188" iyz="-0.00003999" izz="0.00025261" />
    </inertial>
    <visual>
      <origin xyz="0 0 0" rpy="0 0 0" />
      <geometry>
        <mesh filename="../xhand1pro/xhand_right/meshes/right_hand_link.STL" />
      </geometry>
      <material name="">
        <color rgba="0.502 0.502 0.502 1" />
      </material>
    </visual>
    <collision>
      <origin xyz="0 0 0" rpy="0 0 0" />
      <geometry>
        <mesh filename="../xhand1pro/xhand_right/meshes/right_hand_link.STL" />
      </geometry>
    </collision>
  </link><link name="right_hand_ee_link">
    <inertial>
      <origin xyz="-3.45924137720922E-17 -4.87109193722268E-18 0" rpy="0 0 0" />
      <mass value="0.001" />
      <inertia ixx="1e-8" ixy="0" ixz="0" iyy="1e-8" iyz="0" izz="1e-8" />
    </inertial>
    <visual>
      <origin xyz="0 0 0" rpy="0 0 0" />
      <geometry>
        <mesh filename="../xhand1pro/xhand_right/meshes/right_hand_ee_link.STL" />
      </geometry>
      <material name="">
        <color rgba="0.055 0.055 0.063 1" />
      </material>
    </visual>
    <collision>
      <origin xyz="0 0 0" rpy="0 0 0" />
      <geometry>
        <mesh filename="../xhand1pro/xhand_right/meshes/right_hand_ee_link.STL" />
      </geometry>
    </collision>
  </link><joint name="right_hand_ee_joint" type="fixed">
    <origin xyz="0 0 0.055" rpy="0 0 0" />
    <parent link="right_hand_link" />
    <child link="right_hand_ee_link" />
    <axis xyz="0 0 0" />
    <dynamics damping="0" friction="0" />
  </joint><link name="right_hand_light_link">
    <inertial>
      <origin xyz="-0.0183865507256068 8.38941239751447E-06 -0.0148986861134992" rpy="0 0 0" />
      <mass value="0.001" />
      <inertia ixx="1e-8" ixy="0" ixz="0" iyy="1e-8" iyz="0" izz="1e-8" />
    </inertial>
    <visual>
      <origin xyz="0 0 0" rpy="0 0 0" />
      <geometry>
        <mesh filename="../xhand1pro/xhand_right/meshes/right_hand_light_link.STL" />
      </geometry>
      <material name="">
        <color rgba="0.553 0.671 1.0 1" />
      </material>
    </visual>
    <collision>
      <origin xyz="0 0 0" rpy="0 0 0" />
      <geometry>
        <mesh filename="../xhand1pro/xhand_right/meshes/right_hand_light_link.STL" />
      </geometry>
    </collision>
  </link><joint name="right_hand_light_joint" type="fixed">
    <origin xyz="0 0 0.055" rpy="0 0 0" />
    <parent link="right_hand_link" />
    <child link="right_hand_light_link" />
    <axis xyz="0 0 0" />
    <dynamics damping="0" friction="0" />
  </joint><link name="right_hand_dorsum_link">
    <inertial>
      <origin xyz="-0.012040002901393 -0.000369914994062156 0.00948736278884796" rpy="0 0 0" />
      <mass value="0.001" />
      <inertia ixx="1e-8" ixy="0" ixz="0" iyy="1e-8" iyz="0" izz="1e-8" />
    </inertial>
    <visual>
      <origin xyz="0 0 0" rpy="0 0 0" />
      <geometry>
        <mesh filename="../xhand1pro/xhand_right/meshes/right_hand_dorsum_link.STL" />
      </geometry>
      <material name="">
        <color rgba="0.941 0.941 0.941 1" />
      </material>
    </visual>
    <collision>
      <origin xyz="0 0 0" rpy="0 0 0" />
      <geometry>
        <mesh filename="../xhand1pro/xhand_right/meshes/right_hand_dorsum_link.STL" />
      </geometry>
    </collision>
  </link><joint name="right_hand_dorsum_joint" type="fixed">
    <origin xyz="0 0 0.055" rpy="0 0 0" />
    <parent link="right_hand_link" />
    <child link="right_hand_dorsum_link" />
    <axis xyz="0 0 0" />
    <dynamics damping="0" friction="0" />
  </joint><link name="right_hand_palm_link">
    <inertial>
      <origin xyz="0.00799748261577538 0.0113290888340896 -0.00315968348545233" rpy="0 0 0" />
      <mass value="0.001" />
      <inertia ixx="1e-8" ixy="0" ixz="0" iyy="1e-8" iyz="0" izz="1e-8" />
    </inertial>
    <visual>
      <origin xyz="0 0 0" rpy="0 0 0" />
      <geometry>
        <mesh filename="../xhand1pro/xhand_right/meshes/right_hand_palm_link.STL" />
      </geometry>
      <material name="">
        <color rgba="0.055 0.055 0.063 1" />
      </material>
    </visual>
    <collision>
      <origin xyz="0 0 0" rpy="0 0 0" />
      <geometry>
        <mesh filename="../xhand1pro/xhand_right/meshes/right_hand_palm_link.STL" />
      </geometry>
    </collision>
  </link><joint name="right_hand_palm_joint" type="fixed">
    <origin xyz="0 0 0.055" rpy="0 0 0" />
    <parent link="right_hand_link" />
    <child link="right_hand_palm_link" />
    <axis xyz="0 0 0" />
    <dynamics damping="0" friction="0" />
  </joint><link name="right_hand_thumb_bend_link">
    <inertial>
      <origin xyz="0.00301003596008698 0.0112336071484652 0.000800179555045841" rpy="0 0 0" />
      <mass value="0.00581743" />
      <inertia ixx="0.00000044" ixy="0.0" ixz="-0.00000002" iyy="0.00000043" iyz="-0.00000007" izz="0.00000033" />
    </inertial>
    <visual>
      <origin xyz="0 0 0" rpy="0 0 0" />
      <geometry>
        <mesh filename="../xhand1pro/xhand_right/meshes/right_hand_thumb_bend_link.STL" />
      </geometry>
      <material name="">
        <color rgba="0.055 0.055 0.063 1" />
      </material>
    </visual>
    <collision>
      <origin xyz="0 0 0" rpy="0 0 0" />
      <geometry>
        <mesh filename="../xhand1pro/xhand_right/meshes/right_hand_thumb_bend_link.STL" />
      </geometry>
    </collision>
  </link><joint name="right_hand_thumb_bend_joint" type="revolute">
    <origin xyz="0.020417 0.028872 0.035928" rpy="0.61087 0 0" />
    <parent link="right_hand_link" />
    <child link="right_hand_thumb_bend_link" />
    <axis xyz="0 0 -1" />
    <limit lower="0" upper="1.309" effort="0.295" velocity="2" />
    <dynamics damping="0" friction="0" />
  </joint><link name="right_hand_thumb_rota_link1">
    <inertial>
      <origin xyz="2.60266752367955E-06 0.0165208186982079 -0.00460074294999319" rpy="0 0 0" />
      <mass value="0.07903209" />
      <inertia ixx="0.00001769" ixy="-0.00000245" ixz="-0.00000202" iyy="0.00001031" iyz="-0.00000447" izz="0.00001248" />
    </inertial>
    <visual>
      <origin xyz="0 0 0" rpy="0 0 0" />
      <geometry>
        <mesh filename="../xhand1pro/xhand_right/meshes/right_hand_thumb_rota_link1.STL" />
      </geometry>
      <material name="">
        <color rgba="0.055 0.055 0.063 1" />
      </material>
    </visual>
    <collision>
      <origin xyz="0 0 0" rpy="0 0 0" />
      <geometry>
        <mesh filename="../xhand1pro/xhand_right/meshes/right_hand_thumb_rota_link1.STL" />
      </geometry>
    </collision>
  </link><joint name="right_hand_thumb_rota_joint1" type="revolute">
    <origin xyz="0.0060305 0.022506 0.0055" rpy="0 0 -0.2618" />
    <parent link="right_hand_thumb_bend_link" />
    <child link="right_hand_thumb_rota_link1" />
    <axis xyz="1 0 0" />
    <limit lower="0" upper="1.571" effort="0.884" velocity="1.696" />
    <dynamics damping="0" friction="0" />
  </joint><link name="right_hand_thumb_rotaback_link1">
    <inertial>
      <origin xyz="-1.13064719754058E-06 -0.0153903282476076 -0.0199604382823699" rpy="0 0 0" />
      <mass value="0.001" />
      <inertia ixx="1e-8" ixy="0" ixz="0" iyy="1e-8" iyz="0" izz="1e-8" />
    </inertial>
    <visual>
      <origin xyz="0 0 0" rpy="0 0 0" />
      <geometry>
        <mesh filename="../xhand1pro/xhand_right/meshes/right_hand_thumb_rotaback_link1.STL" />
      </geometry>
      <material name="">
        <color rgba="0.941 0.941 0.941 1" />
      </material>
    </visual>
    <collision>
      <origin xyz="0 0 0" rpy="0 0 0" />
      <geometry>
        <mesh filename="../xhand1pro/xhand_right/meshes/right_hand_thumb_rotaback_link1.STL" />
      </geometry>
    </collision>
  </link><joint name="right_hand_thumb_rotaback_joint1" type="fixed">
    <origin xyz="0 0.0345 0" rpy="0 0 0" />
    <parent link="right_hand_thumb_rota_link1" />
    <child link="right_hand_thumb_rotaback_link1" />
    <axis xyz="0 0 0" />
    <dynamics damping="0" friction="0" />
  </joint><link name="right_hand_thumb_rota_link2">
    <inertial>
      <origin xyz="3.42623558556888E-05 0.02219346528376 -0.00361834238923307" rpy="0 0 0" />
      <mass value="0.03780633" />
      <inertia ixx="0.00000534" ixy="-0.00000075" ixz="-0.00000047" iyy="0.00000303" iyz="-0.00000145" izz="0.00000435" />
    </inertial>
    <visual>
      <origin xyz="0 0 0" rpy="0 0 0" />
      <geometry>
        <mesh filename="../xhand1pro/xhand_right/meshes/right_hand_thumb_rota_link2.STL" />
      </geometry>
      <material name="">
        <color rgba="0.055 0.055 0.063 1" />
      </material>
    </visual>
    <collision>
      <origin xyz="0 0 0" rpy="0 0 0" />
      <geometry>
        <mesh filename="../xhand1pro/xhand_right/meshes/right_hand_thumb_rota_link2.STL" />
      </geometry>
    </collision>
  </link><joint name="right_hand_thumb_rota_joint2" type="revolute">
    <origin xyz="0 0.0345 0" rpy="0 0 0" />
    <parent link="right_hand_thumb_rota_link1" />
    <child link="right_hand_thumb_rota_link2" />
    <axis xyz="1 0 0" />
    <limit lower="0" upper="1.571" effort="0.302" velocity="1.98" />
    <dynamics damping="0" friction="0" />
  </joint><link name="right_hand_thumb_rotaback_link2">
    <inertial>
      <origin xyz="-3.26466309269885E-05 -0.0136068734039633 -0.0111115385290224" rpy="0 0 0" />
      <mass value="0.001" />
      <inertia ixx="1e-8" ixy="0" ixz="0" iyy="1e-8" iyz="0" izz="1e-8" />
    </inertial>
    <visual>
      <origin xyz="0 0 0" rpy="0 0 0" />
      <geometry>
        <mesh filename="../xhand1pro/xhand_right/meshes/right_hand_thumb_rotaback_link2.STL" />
      </geometry>
      <material name="">
        <color rgba="0.941 0.941 0.941 1" />
      </material>
    </visual>
    <collision>
      <origin xyz="0 0 0" rpy="0 0 0" />
      <geometry>
        <mesh filename="../xhand1pro/xhand_right/meshes/right_hand_thumb_rotaback_link2.STL" />
      </geometry>
    </collision>
  </link><joint name="right_hand_thumb_rotaback_joint2" type="fixed">
    <origin xyz="0 0.0374168958538642 -0.00450000000001719" rpy="0 0 0" />
    <parent link="right_hand_thumb_rota_link2" />
    <child link="right_hand_thumb_rotaback_link2" />
    <axis xyz="0 0 0" />
    <dynamics damping="0" friction="0" />
  </joint><link name="right_hand_thumb_rota_link3">
    <inertial>
      <origin xyz="2.85344851238926E-06 0.01563912301792 -0.000426212544824674" rpy="0 0 0" />
      <mass value="0.00650707" />
      <inertia ixx="0.00000047" ixy="-0.00000006" ixz="-0.00000004" iyy="0.00000033" iyz="-0.00000011" izz="0.00000046" />
    </inertial>
    <visual>
      <origin xyz="0 0 0" rpy="0 0 0" />
      <geometry>
        <mesh filename="../xhand1pro/xhand_right/meshes/right_hand_thumb_rota_link3.STL" />
      </geometry>
      <material name="">
        <color rgba="0.055 0.055 0.063 1" />
      </material>
    </visual>
    <collision>
      <origin xyz="0 0 0" rpy="0 0 0" />
      <geometry>
        <mesh filename="../xhand1pro/xhand_right/meshes/right_hand_thumb_rota_link3.STL" />
      </geometry>
    </collision>
  </link><joint name="right_hand_thumb_rota_joint3" type="revolute">
    <origin xyz="0 0.037417 -0.0045" rpy="0 0 0" />
    <parent link="right_hand_thumb_rota_link2" />
    <child link="right_hand_thumb_rota_link3" />
    <axis xyz="1 0 0" />
    <limit lower="0" upper="1.571" effort="0.295" velocity="2" />
    <dynamics damping="0" friction="0" />
  </joint><link name="right_hand_thumb_rota_link4">
    <inertial>
      <origin xyz="-2.46677678283902E-14 -5.55111512312578E-17 0" rpy="0 0 0" />
      <mass value="0.001" />
      <inertia ixx="1e-8" ixy="0" ixz="0" iyy="1e-8" iyz="0" izz="1e-8" />
    </inertial>
    <visual>
      <origin xyz="0 0 0" rpy="0 0 0" />
      <geometry>
        <mesh filename="../xhand1pro/xhand_right/meshes/right_hand_thumb_rota_link4.STL" />
      </geometry>
      <material name="">
        <color rgba="0.055 0.055 0.063 1" />
      </material>
    </visual>
    <collision>
      <origin xyz="0 0 0" rpy="0 0 0" />
      <geometry>
        <mesh filename="../xhand1pro/xhand_right/meshes/right_hand_thumb_rota_link4.STL" />
      </geometry>
    </collision>
  </link><joint name="right_hand_thumb_rota_joint4" type="fixed">
    <origin xyz="0 0.0181728187019062 0.00791114210898186" rpy="0 0 0" />
    <parent link="right_hand_thumb_rota_link3" />
    <child link="right_hand_thumb_rota_link4" />
    <axis xyz="0 0 0" />
    <dynamics damping="0" friction="0" />
  </joint><link name="right_hand_thumb_rota_link5">
    <inertial>
      <origin xyz="-2.46747067222941E-14 -8.32667268468867E-17 -1.38777878078145E-17" rpy="0 0 0" />
      <mass value="0.001" />
      <inertia ixx="1e-8" ixy="0" ixz="0" iyy="1e-8" iyz="0" izz="1e-8" />
    </inertial>
    <visual>
      <origin xyz="0 0 0" rpy="0 0 0" />
      <geometry>
        <mesh filename="../xhand1pro/xhand_right/meshes/right_hand_thumb_rota_link5.STL" />
      </geometry>
      <material name="">
        <color rgba="0.055 0.055 0.063 1" />
      </material>
    </visual>
    <collision>
      <origin xyz="0 0 0" rpy="0 0 0" />
      <geometry>
        <mesh filename="../xhand1pro/xhand_right/meshes/right_hand_thumb_rota_link5.STL" />
      </geometry>
    </collision>
  </link><joint name="right_hand_thumb_rota_joint5" type="fixed">
    <origin xyz="0 0.0312512504715699 0" rpy="0 0 0" />
    <parent link="right_hand_thumb_rota_link3" />
    <child link="right_hand_thumb_rota_link5" />
    <axis xyz="0 0 0" />
    <dynamics damping="0" friction="0" />
  </joint><link name="right_hand_index_bend_link">
    <inertial>
      <origin xyz="0.000800179544238866 -1.23512311489549E-15 0.0116298858976673" rpy="0 0 0" />
      <mass value="0.00581743" />
      <inertia ixx="0.00000043" ixy="0.0" ixz="-0.00000004" iyy="0.00000042" iyz="0.00000001" izz="0.00000032" />
    </inertial>
    <visual>
      <origin xyz="0 0 0" rpy="0 0 0" />
      <geometry>
        <mesh filename="../xhand1pro/xhand_right/meshes/right_hand_index_bend_link.STL" />
      </geometry>
      <material name="">
        <color rgba="0.055 0.055 0.063 1" />
      </material>
    </visual>
    <collision>
      <origin xyz="0 0 0" rpy="0 0 0" />
      <geometry>
        <mesh filename="../xhand1pro/xhand_right/meshes/right_hand_index_bend_link.STL" />
      </geometry>
    </collision>
  </link><joint name="right_hand_index_bend_joint" type="revolute">
    <origin xyz="0.0045 0.032961 0.096293" rpy="0 0 0" />
    <parent link="right_hand_link" />
    <child link="right_hand_index_bend_link" />
    <axis xyz="-1 0 0" />
    <limit lower="-0.262" upper="1.396" effort="0.295" velocity="2" />
    <dynamics damping="0" friction="0" />
  </joint><link name="right_hand_index_rota_link1">
    <inertial>
      <origin xyz="-0.00460077454805617 2.64962858453205E-06 0.0165208268829082" rpy="0 0 0" />
      <mass value="0.07903209" />
      <inertia ixx="0.00001597" ixy="-0.00000011" ixz="-0.00000056" iyy="0.00001854" iyz="-0.00000003" izz="0.00000598" />
    </inertial>
    <visual>
      <origin xyz="0 0 0" rpy="0 0 0" />
      <geometry>
        <mesh filename="../xhand1pro/xhand_right/meshes/right_hand_index_rota_link1.STL" />
      </geometry>
      <material name="">
        <color rgba="0.055 0.055 0.063 1" />
      </material>
    </visual>
    <collision>
      <origin xyz="0 0 0" rpy="0 0 0" />
      <geometry>
        <mesh filename="../xhand1pro/xhand_right/meshes/right_hand_index_rota_link1.STL" />
      </geometry>
    </collision>
  </link><joint name="right_hand_index_rota_joint1" type="revolute">
    <origin xyz="0.0055 0 0.0233" rpy="0 0 0" />
    <parent link="right_hand_index_bend_link" />
    <child link="right_hand_index_rota_link1" />
    <axis xyz="0 1 0" />
    <limit lower="0" upper="1.571" effort="0.884" velocity="1.696" />
    <dynamics damping="0" friction="0" />
  </joint><link name="right_hand_index_rotaback_link1">
    <inertial>
      <origin xyz="-0.0199604212697389 -1.11555281114006E-06 -0.0153905493917118" rpy="0 0 0" />
      <mass value="0.001" />
      <inertia ixx="1e-8" ixy="0" ixz="0" iyy="1e-8" iyz="0" izz="1e-8" />
    </inertial>
    <visual>
      <origin xyz="0 0 0" rpy="0 0 0" />
      <geometry>
        <mesh filename="../xhand1pro/xhand_right/meshes/right_hand_index_rotaback_link1.STL" />
      </geometry>
      <material name="">
        <color rgba="0.941 0.941 0.941 1" />
      </material>
    </visual>
    <collision>
      <origin xyz="0 0 0" rpy="0 0 0" />
      <geometry>
        <mesh filename="../xhand1pro/xhand_right/meshes/right_hand_index_rotaback_link1.STL" />
      </geometry>
    </collision>
  </link><joint name="right_hand_index_rotaback_joint1" type="fixed">
    <origin xyz="0 0 0.0345" rpy="0 0 0" />
    <parent link="right_hand_index_rota_link1" />
    <child link="right_hand_index_rotaback_link1" />
    <axis xyz="0 0 0" />
    <dynamics damping="0" friction="0" />
  </joint><link name="right_hand_index_rota_link2">
    <inertial>
      <origin xyz="-0.00361835937101106 3.42636230876783E-05 0.0221934729698274" rpy="0 0 0" />
      <mass value="0.03780633" />
      <inertia ixx="0.00000528" ixy="0.00000001" ixz="0.00000013" iyy="0.00000557" iyz="0.00000005" izz="0.00000187" />
    </inertial>
    <visual>
      <origin xyz="0 0 0" rpy="0 0 0" />
      <geometry>
        <mesh filename="../xhand1pro/xhand_right/meshes/right_hand_index_rota_link2.STL" />
      </geometry>
      <material name="">
        <color rgba="0.055 0.055 0.063 1" />
      </material>
    </visual>
    <collision>
      <origin xyz="0 0 0" rpy="0 0 0" />
      <geometry>
        <mesh filename="../xhand1pro/xhand_right/meshes/right_hand_index_rota_link2.STL" />
      </geometry>
    </collision>
  </link><joint name="right_hand_index_rota_joint2" type="revolute">
    <origin xyz="0 0 0.0345" rpy="0 0 0" />
    <parent link="right_hand_index_rota_link1" />
    <child link="right_hand_index_rota_link2" />
    <axis xyz="0 1 0" />
    <limit lower="0" upper="1.571" effort="0.302" velocity="1.98" />
    <dynamics damping="0" friction="0" />
  </joint><link name="right_hand_index_rotaback_link2">
    <inertial>
      <origin xyz="-0.0111115598196365 -3.27218405192856E-05 -0.013607038431935" rpy="0 0 0" />
      <mass value="0.001" />
      <inertia ixx="1e-8" ixy="0" ixz="0" iyy="1e-8" iyz="0" izz="1e-8" />
    </inertial>
    <visual>
      <origin xyz="0 0 0" rpy="0 0 0" />
      <geometry>
        <mesh filename="../xhand1pro/xhand_right/meshes/right_hand_index_rotaback_link2.STL" />
      </geometry>
      <material name="">
        <color rgba="0.941 0.941 0.941 1" />
      </material>
    </visual>
    <collision>
      <origin xyz="0 0 0" rpy="0 0 0" />
      <geometry>
        <mesh filename="../xhand1pro/xhand_right/meshes/right_hand_index_rotaback_link2.STL" />
      </geometry>
    </collision>
  </link><joint name="right_hand_index_rotaback_joint2" type="fixed">
    <origin xyz="-0.00450000001858888 0 0.0374168958516306" rpy="0 0 0" />
    <parent link="right_hand_index_rota_link2" />
    <child link="right_hand_index_rotaback_link2" />
    <axis xyz="0 0 0" />
    <dynamics damping="0" friction="0" />
  </joint><link name="right_hand_index_rota_link3">
    <inertial>
      <origin xyz="-0.000426169388122585 2.78802808797302E-06 0.0156390611297944" rpy="0 0 0" />
      <mass value="0.00650707" />
      <inertia ixx="0.00000052" ixy="0.0" ixz="0.00000002" iyy="0.00000049" iyz="-0.00000001" izz="0.00000025" />
    </inertial>
    <visual>
      <origin xyz="0 0 0" rpy="0 0 0" />
      <geometry>
        <mesh filename="../xhand1pro/xhand_right/meshes/right_hand_index_rota_link3.STL" />
      </geometry>
      <material name="">
        <color rgba="0.055 0.055 0.063 1" />
      </material>
    </visual>
    <collision>
      <origin xyz="0 0 0" rpy="0 0 0" />
      <geometry>
        <mesh filename="../xhand1pro/xhand_right/meshes/right_hand_index_rota_link3.STL" />
      </geometry>
    </collision>
  </link><joint name="right_hand_index_rota_joint3" type="revolute">
    <origin xyz="-0.0045 0 0.037417" rpy="0 0 0" />
    <parent link="right_hand_index_rota_link2" />
    <child link="right_hand_index_rota_link3" />
    <axis xyz="0 1 0" />
    <limit lower="0" upper="1.571" effort="0.295" velocity="2" />
    <dynamics damping="0" friction="0" />
  </joint><link name="right_hand_index_rota_link4">
    <inertial>
      <origin xyz="3.38271077815477E-16 -2.48898124333152E-14 0" rpy="0 0 0" />
      <mass value="0.001" />
      <inertia ixx="1e-8" ixy="0" ixz="0" iyy="1e-8" iyz="0" izz="1e-8" />
    </inertial>
    <visual>
      <origin xyz="0 0 0" rpy="0 0 0" />
      <geometry>
        <mesh filename="../xhand1pro/xhand_right/meshes/right_hand_index_rota_link4.STL" />
      </geometry>
      <material name="">
        <color rgba="0.055 0.055 0.063 1" />
      </material>
    </visual>
    <collision>
      <origin xyz="0 0 0" rpy="0 0 0" />
      <geometry>
        <mesh filename="../xhand1pro/xhand_right/meshes/right_hand_index_rota_link4.STL" />
      </geometry>
    </collision>
  </link><joint name="right_hand_index_rota_joint4" type="fixed">
    <origin xyz="0.0079111421089901 0 0.0181728187019025" rpy="0 0 0" />
    <parent link="right_hand_index_rota_link3" />
    <child link="right_hand_index_rota_link4" />
    <axis xyz="0 0 0" />
    <limit lower="0" upper="0" effort="0" velocity="0" />
    <dynamics damping="0" friction="0" />
  </joint><link name="right_hand_index_rota_link5">
    <inertial>
      <origin xyz="3.35668992601512E-16 -2.48967513272191E-14 0" rpy="0 0 0" />
      <mass value="0.001" />
      <inertia ixx="1e-8" ixy="0" ixz="0" iyy="1e-8" iyz="0" izz="1e-8" />
    </inertial>
    <visual>
      <origin xyz="0 0 0" rpy="0 0 0" />
      <geometry>
        <mesh filename="../xhand1pro/xhand_right/meshes/right_hand_index_rota_link5.STL" />
      </geometry>
      <material name="">
        <color rgba="0.055 0.055 0.063 1" />
      </material>
    </visual>
    <collision>
      <origin xyz="0 0 0" rpy="0 0 0" />
      <geometry>
        <mesh filename="../xhand1pro/xhand_right/meshes/right_hand_index_rota_link5.STL" />
      </geometry>
    </collision>
  </link><joint name="right_hand_index_rota_joint5" type="fixed">
    <origin xyz="0 0 0.0312512504715699" rpy="0 0 0" />
    <parent link="right_hand_index_rota_link3" />
    <child link="right_hand_index_rota_link5" />
    <axis xyz="0 0 0" />
    <dynamics damping="0" friction="0" />
  </joint><link name="right_hand_mid_bend_link">
    <inertial>
      <origin xyz="0.000800179547577836 -1.2490009027033E-15 0.0116298858976673" rpy="0 0 0" />
      <mass value="0.00581743" />
      <inertia ixx="0.00000043" ixy="0.0" ixz="-0.00000007" iyy="0.00000044" iyz="0.00000001" izz="0.00000033" />
    </inertial>
    <visual>
      <origin xyz="0 0 0" rpy="0 0 0" />
      <geometry>
        <mesh filename="../xhand1pro/xhand_right/meshes/right_hand_mid_bend_link.STL" />
      </geometry>
      <material name="">
        <color rgba="0.055 0.055 0.063 1" />
      </material>
    </visual>
    <collision>
      <origin xyz="0 0 0" rpy="0 0 0" />
      <geometry>
        <mesh filename="../xhand1pro/xhand_right/meshes/right_hand_mid_bend_link.STL" />
      </geometry>
    </collision>
  </link><joint name="right_hand_mid_bend_joint" type="revolute">
    <origin xyz="0.0045 0.0086396 0.098793" rpy="0 0 0" />
    <parent link="right_hand_link" />
    <child link="right_hand_mid_bend_link" />
    <axis xyz="-1 0 0" />
    <limit lower="-0.785" upper="0.262" effort="0.295" velocity="2" />
    <dynamics damping="0" friction="0" />
  </joint><link name="right_hand_mid_rota_link1">
    <inertial>
      <origin xyz="-0.004600775224834 2.64997904275005E-06 0.0165208263269908" rpy="0 0 0" />
      <mass value="0.07903209" />
      <inertia ixx="0.00001597" ixy="-0.00000011" ixz="-0.00000056" iyy="0.00001854" iyz="-0.00000003" izz="0.00000598" />
    </inertial>
    <visual>
      <origin xyz="0 0 0" rpy="0 0 0" />
      <geometry>
        <mesh filename="../xhand1pro/xhand_right/meshes/right_hand_mid_rota_link1.STL" />
      </geometry>
      <material name="">
        <color rgba="0.055 0.055 0.063 1" />
      </material>
    </visual>
    <collision>
      <origin xyz="0 0 0" rpy="0 0 0" />
      <geometry>
        <mesh filename="../xhand1pro/xhand_right/meshes/right_hand_mid_rota_link1.STL" />
      </geometry>
    </collision>
  </link><joint name="right_hand_mid_rota_joint1" type="revolute">
    <origin xyz="0.0055 0 0.0233" rpy="0 0 0" />
    <parent link="right_hand_mid_bend_link" />
    <child link="right_hand_mid_rota_link1" />
    <axis xyz="0 1 0" />
    <limit lower="0" upper="1.571" effort="0.884" velocity="1.696" />
    <dynamics damping="0" friction="0" />
  </joint><link name="right_hand_mid_rotaback_link1">
    <inertial>
      <origin xyz="-0.0199604212697355 -1.11555281103945E-06 -0.0153905493916313" rpy="0 0 0" />
      <mass value="0.001" />
      <inertia ixx="1e-8" ixy="0" ixz="0" iyy="1e-8" iyz="0" izz="1e-8" />
    </inertial>
    <visual>
      <origin xyz="0 0 0" rpy="0 0 0" />
      <geometry>
        <mesh filename="../xhand1pro/xhand_right/meshes/right_hand_mid_rotaback_link1.STL" />
      </geometry>
      <material name="">
        <color rgba="0.941 0.941 0.941 1" />
      </material>
    </visual>
    <collision>
      <origin xyz="0 0 0" rpy="0 0 0" />
      <geometry>
        <mesh filename="../xhand1pro/xhand_right/meshes/right_hand_mid_rotaback_link1.STL" />
      </geometry>
    </collision>
  </link><joint name="right_hand_mid_rotaback_joint1" type="fixed">
    <origin xyz="0 0 0.0345" rpy="0 0 0" />
    <parent link="right_hand_mid_rota_link1" />
    <child link="right_hand_mid_rotaback_link1" />
    <axis xyz="0 0 0" />
    <dynamics damping="0" friction="0" />
  </joint><link name="right_hand_mid_rota_link2">
    <inertial>
      <origin xyz="-0.00361835937101111 3.42636230876801E-05 0.0221934729698274" rpy="0 0 0" />
      <mass value="0.03780633" />
      <inertia ixx="0.00000528" ixy="0.00000001" ixz="0.00000013" iyy="0.00000557" iyz="0.00000005" izz="0.00000187" />
    </inertial>
    <visual>
      <origin xyz="0 0 0" rpy="0 0 0" />
      <geometry>
        <mesh filename="../xhand1pro/xhand_right/meshes/right_hand_mid_rota_link2.STL" />
      </geometry>
      <material name="">
        <color rgba="0.055 0.055 0.063 1" />
      </material>
    </visual>
    <collision>
      <origin xyz="0 0 0" rpy="0 0 0" />
      <geometry>
        <mesh filename="../xhand1pro/xhand_right/meshes/right_hand_mid_rota_link2.STL" />
      </geometry>
    </collision>
  </link><joint name="right_hand_mid_rota_joint2" type="revolute">
    <origin xyz="0 0 0.0345" rpy="0 0 0" />
    <parent link="right_hand_mid_rota_link1" />
    <child link="right_hand_mid_rota_link2" />
    <axis xyz="0 1 0" />
    <limit lower="0" upper="1.571" effort="0.302" velocity="1.98" />
    <dynamics damping="0" friction="0" />
  </joint><link name="right_hand_mid_rotaback_link2">
    <inertial>
      <origin xyz="-0.011111559999976 -3.2722013561564E-05 -0.0136070382532542" rpy="0 0 0" />
      <mass value="0.001" />
      <inertia ixx="1e-8" ixy="0" ixz="0" iyy="1e-8" iyz="0" izz="1e-8" />
    </inertial>
    <visual>
      <origin xyz="0 0 0" rpy="0 0 0" />
      <geometry>
        <mesh filename="../xhand1pro/xhand_right/meshes/right_hand_mid_rotaback_link2.STL" />
      </geometry>
      <material name="">
        <color rgba="0.941 0.941 0.941 1" />
      </material>
    </visual>
    <collision>
      <origin xyz="0 0 0" rpy="0 0 0" />
      <geometry>
        <mesh filename="../xhand1pro/xhand_right/meshes/right_hand_mid_rotaback_link2.STL" />
      </geometry>
    </collision>
  </link><joint name="right_hand_mid_rotaback_joint2" type="fixed">
    <origin xyz="-0.00450000001858886 0 0.0374168958516306" rpy="0 0 0" />
    <parent link="right_hand_mid_rota_link2" />
    <child link="right_hand_mid_rotaback_link2" />
    <axis xyz="0 0 0" />
    <dynamics damping="0" friction="0" />
  </joint><link name="right_hand_mid_rota_link3">
    <inertial>
      <origin xyz="-0.000426169794988716 2.78678852924825E-06 0.0156390627834363" rpy="0 0 0" />
      <mass value="0.00650707" />
      <inertia ixx="0.00000052" ixy="0.0" ixz="0.00000002" iyy="0.00000049" iyz="-0.00000001" izz="0.00000025" />
    </inertial>
    <visual>
      <origin xyz="0 0 0" rpy="0 0 0" />
      <geometry>
        <mesh filename="../xhand1pro/xhand_right/meshes/right_hand_mid_rota_link3.STL" />
      </geometry>
      <material name="">
        <color rgba="0.055 0.055 0.063 1" />
      </material>
    </visual>
    <collision>
      <origin xyz="0 0 0" rpy="0 0 0" />
      <geometry>
        <mesh filename="../xhand1pro/xhand_right/meshes/right_hand_mid_rota_link3.STL" />
      </geometry>
    </collision>
  </link><joint name="right_hand_mid_rota_joint3" type="revolute">
    <origin xyz="-0.0045 0 0.037417" rpy="0 0 0" />
    <parent link="right_hand_mid_rota_link2" />
    <child link="right_hand_mid_rota_link3" />
    <axis xyz="0 1 0" />
    <limit lower="0" upper="1.571" effort="0.295" velocity="2" />
    <dynamics damping="0" friction="0" />
  </joint><link name="right_hand_mid_rota_link4">
    <inertial>
      <origin xyz="2.8796409701215E-16 -2.57207449783081E-14 2.77555756156289E-17" rpy="0 0 0" />
      <mass value="0.001" />
      <inertia ixx="1e-8" ixy="0" ixz="0" iyy="1e-8" iyz="0" izz="1e-8" />
    </inertial>
    <visual>
      <origin xyz="0 0 0" rpy="0 0 0" />
      <geometry>
        <mesh filename="../xhand1pro/xhand_right/meshes/right_hand_mid_rota_link4.STL" />
      </geometry>
      <material name="">
        <color rgba="0.055 0.055 0.063 1" />
      </material>
    </visual>
    <collision>
      <origin xyz="0 0 0" rpy="0 0 0" />
      <geometry>
        <mesh filename="../xhand1pro/xhand_right/meshes/right_hand_mid_rota_link4.STL" />
      </geometry>
    </collision>
  </link><joint name="right_hand_mid_rota_joint4" type="fixed">
    <origin xyz="0.00791114210899072 0 0.0181728187019025" rpy="0 0 0" />
    <parent link="right_hand_mid_rota_link3" />
    <child link="right_hand_mid_rota_link4" />
    <axis xyz="0 0 0" />
    <dynamics damping="0" friction="0" />
  </joint><link name="right_hand_mid_rota_link5">
    <inertial>
      <origin xyz="2.88831458750138E-16 -2.52263487876547E-14 8.32667268468867E-17" rpy="0 0 0" />
      <mass value="0.001" />
      <inertia ixx="1e-8" ixy="0" ixz="0" iyy="1e-8" iyz="0" izz="1e-8" />
    </inertial>
    <visual>
      <origin xyz="0 0 0" rpy="0 0 0" />
      <geometry>
        <mesh filename="../xhand1pro/xhand_right/meshes/right_hand_mid_rota_link5.STL" />
      </geometry>
      <material name="">
        <color rgba="0.055 0.055 0.063 1" />
      </material>
    </visual>
    <collision>
      <origin xyz="0 0 0" rpy="0 0 0" />
      <geometry>
        <mesh filename="../xhand1pro/xhand_right/meshes/right_hand_mid_rota_link5.STL" />
      </geometry>
    </collision>
  </link><joint name="right_hand_mid_rota_joint5" type="fixed">
    <origin xyz="0 0 0.0312512504715699" rpy="0 0 0" />
    <parent link="right_hand_mid_rota_link3" />
    <child link="right_hand_mid_rota_link5" />
    <axis xyz="0 0 0" />
    <dynamics damping="0" friction="0" />
  </joint><link name="right_hand_ring_bend_link">
    <inertial>
      <origin xyz="0.000800179544817464 -1.23685783837146E-15 0.0116298858976672" rpy="0 0 0" />
      <mass value="0.00581743" />
      <inertia ixx="0.00000043" ixy="0.0" ixz="-0.00000007" iyy="0.00000044" iyz="0.00000001" izz="0.00000033" />
    </inertial>
    <visual>
      <origin xyz="0 0 0" rpy="0 0 0" />
      <geometry>
        <mesh filename="../xhand1pro/xhand_right/meshes/right_hand_ring_bend_link.STL" />
      </geometry>
      <material name="">
        <color rgba="0.055 0.055 0.063 1" />
      </material>
    </visual>
    <collision>
      <origin xyz="0 0 0" rpy="0 0 0" />
      <geometry>
        <mesh filename="../xhand1pro/xhand_right/meshes/right_hand_ring_bend_link.STL" />
      </geometry>
    </collision>
  </link><joint name="right_hand_ring_bend_joint" type="revolute">
    <origin xyz="0.0045 -0.014087 0.094293" rpy="0 0 0" />
    <parent link="right_hand_link" />
    <child link="right_hand_ring_bend_link" />
    <axis xyz="-1 0 0" />
    <limit lower="-0.785" upper="0.262" effort="0.295" velocity="2" />
    <dynamics damping="0" friction="0" />
  </joint><link name="right_hand_ring_rota_link1">
    <inertial>
      <origin xyz="-0.00460077434233608 2.6495532504528E-06 0.0165208271725728" rpy="0 0 0" />
      <mass value="0.07903209" />
      <inertia ixx="0.00001597" ixy="-0.00000011" ixz="-0.00000056" iyy="0.00001854" iyz="-0.00000003" izz="0.00000598" />
    </inertial>
    <visual>
      <origin xyz="0 0 0" rpy="0 0 0" />
      <geometry>
        <mesh filename="../xhand1pro/xhand_right/meshes/right_hand_ring_rota_link1.STL" />
      </geometry>
      <material name="">
        <color rgba="0.055 0.055 0.063 1" />
      </material>
    </visual>
    <collision>
      <origin xyz="0 0 0" rpy="0 0 0" />
      <geometry>
        <mesh filename="../xhand1pro/xhand_right/meshes/right_hand_ring_rota_link1.STL" />
      </geometry>
    </collision>
  </link><joint name="right_hand_ring_rota_joint1" type="revolute">
    <origin xyz="0.0055 0 0.0233" rpy="0 0 0" />
    <parent link="right_hand_ring_bend_link" />
    <child link="right_hand_ring_rota_link1" />
    <axis xyz="0 1 0" />
    <limit lower="0" upper="1.571" effort="0.884" velocity="1.696" />
    <dynamics damping="0" friction="0" />
  </joint><link name="right_hand_ring_rotaback_link1">
    <inertial>
      <origin xyz="-0.0199604212697358 -1.11555281101863E-06 -0.0153905493916261" rpy="0 0 0" />
      <mass value="0.001" />
      <inertia ixx="1e-8" ixy="0" ixz="0" iyy="1e-8" iyz="0" izz="1e-8" />
    </inertial>
    <visual>
      <origin xyz="0 0 0" rpy="0 0 0" />
      <geometry>
        <mesh filename="../xhand1pro/xhand_right/meshes/right_hand_ring_rotaback_link1.STL" />
      </geometry>
      <material name="">
        <color rgba="0.941 0.941 0.941 1" />
      </material>
    </visual>
    <collision>
      <origin xyz="0 0 0" rpy="0 0 0" />
      <geometry>
        <mesh filename="../xhand1pro/xhand_right/meshes/right_hand_ring_rotaback_link1.STL" />
      </geometry>
    </collision>
  </link><joint name="right_hand_ring_rotaback_joint1" type="fixed">
    <origin xyz="0 0 0.0345" rpy="0 0 0" />
    <parent link="right_hand_ring_rota_link1" />
    <child link="right_hand_ring_rotaback_link1" />
    <axis xyz="0 0 0" />
    <dynamics damping="0" friction="0" />
  </joint><link name="right_hand_ring_rota_link2">
    <inertial>
      <origin xyz="-0.00361835937196581 3.42636238935129E-05 0.0221934729716685" rpy="0 0 0" />
      <mass value="0.03780633" />
      <inertia ixx="0.00000528" ixy="0.00000001" ixz="0.00000013" iyy="0.00000557" iyz="0.00000005" izz="0.00000187" />
    </inertial>
    <visual>
      <origin xyz="0 0 0" rpy="0 0 0" />
      <geometry>
        <mesh filename="../xhand1pro/xhand_right/meshes/right_hand_ring_rota_link2.STL" />
      </geometry>
      <material name="">
        <color rgba="0.055 0.055 0.063 1" />
      </material>
    </visual>
    <collision>
      <origin xyz="0 0 0" rpy="0 0 0" />
      <geometry>
        <mesh filename="../xhand1pro/xhand_right/meshes/right_hand_ring_rota_link2.STL" />
      </geometry>
    </collision>
  </link><joint name="right_hand_ring_rota_joint2" type="revolute">
    <origin xyz="0 0 0.0345" rpy="0 0 0" />
    <parent link="right_hand_ring_rota_link1" />
    <child link="right_hand_ring_rota_link2" />
    <axis xyz="0 1 0" />
    <limit lower="0" upper="1.571" effort="0.302" velocity="1.98" />
    <dynamics damping="0" friction="0" />
  </joint><link name="right_hand_ring_rotaback_link2">
    <inertial>
      <origin xyz="-0.0111115604094498 -3.27208199343895E-05 -0.0136070385820325" rpy="0 0 0" />
      <mass value="0.001" />
      <inertia ixx="1e-8" ixy="0" ixz="0" iyy="1e-8" iyz="0" izz="1e-8" />
    </inertial>
    <visual>
      <origin xyz="0 0 0" rpy="0 0 0" />
      <geometry>
        <mesh filename="../xhand1pro/xhand_right/meshes/right_hand_ring_rotaback_link2.STL" />
      </geometry>
      <material name="">
        <color rgba="0.941 0.941 0.941 1" />
      </material>
    </visual>
    <collision>
      <origin xyz="0 0 0" rpy="0 0 0" />
      <geometry>
        <mesh filename="../xhand1pro/xhand_right/meshes/right_hand_ring_rotaback_link2.STL" />
      </geometry>
    </collision>
  </link><joint name="right_hand_ring_rotaback_joint2" type="fixed">
    <origin xyz="-0.00450000001858883 0 0.0374168958516306" rpy="0 0 0" />
    <parent link="right_hand_ring_rota_link2" />
    <child link="right_hand_ring_rotaback_link2" />
    <axis xyz="0 0 0" />
    <dynamics damping="0" friction="0" />
  </joint><link name="right_hand_ring_rota_link3">
    <inertial>
      <origin xyz="-0.000426169587574249 2.78668802122968E-06 0.0156390621636113" rpy="0 0 0" />
      <mass value="0.00650707" />
      <inertia ixx="0.00000052" ixy="0.0" ixz="0.00000002" iyy="0.00000049" iyz="-0.00000001" izz="0.00000025" />
    </inertial>
    <visual>
      <origin xyz="0 0 0" rpy="0 0 0" />
      <geometry>
        <mesh filename="../xhand1pro/xhand_right/meshes/right_hand_ring_rota_link3.STL" />
      </geometry>
      <material name="">
        <color rgba="0.055 0.055 0.063 1" />
      </material>
    </visual>
    <collision>
      <origin xyz="0 0 0" rpy="0 0 0" />
      <geometry>
        <mesh filename="../xhand1pro/xhand_right/meshes/right_hand_ring_rota_link3.STL" />
      </geometry>
    </collision>
  </link><joint name="right_hand_ring_rota_joint3" type="revolute">
    <origin xyz="-0.0045 0 0.037417" rpy="0 0 0" />
    <parent link="right_hand_ring_rota_link2" />
    <child link="right_hand_ring_rota_link3" />
    <axis xyz="0 1 0" />
    <limit lower="0" upper="1.571" effort="0.295" velocity="2" />
    <dynamics damping="0" friction="0" />
  </joint><link name="right_hand_ring_rota_link4">
    <inertial>
      <origin xyz="3.00107161343988E-16 -2.48655263046516E-14 5.55111512312578E-17" rpy="0 0 0" />
      <mass value="0.001" />
      <inertia ixx="1e-8" ixy="0" ixz="0" iyy="1e-8" iyz="0" izz="1e-8" />
    </inertial>
    <visual>
      <origin xyz="0 0 0" rpy="0 0 0" />
      <geometry>
        <mesh filename="../xhand1pro/xhand_right/meshes/right_hand_ring_rota_link4.STL" />
      </geometry>
      <material name="">
        <color rgba="0.055 0.055 0.063 1" />
      </material>
    </visual>
    <collision>
      <origin xyz="0 0 0" rpy="0 0 0" />
      <geometry>
        <mesh filename="../xhand1pro/xhand_right/meshes/right_hand_ring_rota_link4.STL" />
      </geometry>
    </collision>
  </link><joint name="right_hand_ring_rota_joint4" type="fixed">
    <origin xyz="0.00791114210899012 0 0.0181728187019025" rpy="0 0 0" />
    <parent link="right_hand_ring_rota_link3" />
    <child link="right_hand_ring_rota_link4" />
    <axis xyz="0 0 0" />
    <dynamics damping="0" friction="0" />
  </joint><link name="right_hand_ring_rota_link5">
    <inertial>
      <origin xyz="3.11382863937837E-16 -2.48689957516035E-14 0" rpy="0 0 0" />
      <mass value="0.001" />
      <inertia ixx="1e-8" ixy="0" ixz="0" iyy="1e-8" iyz="0" izz="1e-8" />
    </inertial>
    <visual>
      <origin xyz="0 0 0" rpy="0 0 0" />
      <geometry>
        <mesh filename="../xhand1pro/xhand_right/meshes/right_hand_ring_rota_link5.STL" />
      </geometry>
      <material name="">
        <color rgba="0.055 0.055 0.063 1" />
      </material>
    </visual>
    <collision>
      <origin xyz="0 0 0" rpy="0 0 0" />
      <geometry>
        <mesh filename="../xhand1pro/xhand_right/meshes/right_hand_ring_rota_link5.STL" />
      </geometry>
    </collision>
  </link><joint name="right_hand_ring_rota_joint5" type="fixed">
    <origin xyz="0 0 0.0312512504715699" rpy="0 0 0" />
    <parent link="right_hand_ring_rota_link3" />
    <child link="right_hand_ring_rota_link5" />
    <axis xyz="0 0 0" />
    <dynamics damping="0" friction="0" />
  </joint><link name="right_hand_ltspalm_link">
    <inertial>
      <origin xyz="-0.00282840942863086 -0.0108786836911325 0.0259210776367877" rpy="0 0 0" />
      <mass value="0.07212218" />
      <inertia ixx="0.00002482" ixy="0.00000016" ixz="0.00000278" iyy="0.00002565" iyz="0.00000056" izz="0.00000657" />
    </inertial>
    <visual>
      <origin xyz="0 0 0" rpy="0 0 0" />
      <geometry>
        <mesh filename="../xhand1pro/xhand_right/meshes/right_hand_ltspalm_link.STL" />
      </geometry>
      <material name="">
        <color rgba="0.055 0.055 0.063 1" />
      </material>
    </visual>
    <collision>
      <origin xyz="0 0 0" rpy="0 0 0" />
      <geometry>
        <mesh filename="../xhand1pro/xhand_right/meshes/right_hand_ltspalm_link.STL" />
      </geometry>
    </collision>
  </link><joint name="right_hand_ltspalm_joint" type="revolute">
    <origin xyz="0.0115 -0.0265 0.041" rpy="0 0 0" />
    <parent link="right_hand_link" />
    <child link="right_hand_ltspalm_link" />
    <axis xyz="0 0 1" />
    <limit lower="0" upper="0.524" effort="0.295" velocity="2" />
    <dynamics damping="0" friction="0" />
  </joint><link name="right_hand_ltsdorsum_link">
    <inertial>
      <origin xyz="-0.0138519254056295 -0.0110937410955385 0.0132679570693964" rpy="0 0 0" />
      <mass value="0.001" />
      <inertia ixx="1e-8" ixy="0" ixz="0" iyy="1e-8" iyz="0" izz="1e-8" />
    </inertial>
    <visual>
      <origin xyz="0 0 0" rpy="0 0 0" />
      <geometry>
        <mesh filename="../xhand1pro/xhand_right/meshes/right_hand_ltsdorsum_link.STL" />
      </geometry>
      <material name="">
        <color rgba="0.941 0.941 0.941 1" />
      </material>
    </visual>
    <collision>
      <origin xyz="0 0 0" rpy="0 0 0" />
      <geometry>
        <mesh filename="../xhand1pro/xhand_right/meshes/right_hand_ltsdorsum_link.STL" />
      </geometry>
    </collision>
  </link><joint name="right_hand_ltsdorsum_joint" type="fixed">
    <origin xyz="0 0 0" rpy="0 0 0" />
    <parent link="right_hand_ltspalm_link" />
    <child link="right_hand_ltsdorsum_link" />
    <axis xyz="0 0 0" />
    <dynamics damping="0" friction="0" />
  </joint><link name="right_hand_pinky_bend_link">
    <inertial>
      <origin xyz="0.000800179546620094 1.79023462720806E-15 0.0116298858976338" rpy="0 0 0" />
      <mass value="0.00581743" />
      <inertia ixx="0.00000043" ixy="0.0" ixz="-0.00000007" iyy="0.00000044" iyz="0.00000001" izz="0.00000033" />
    </inertial>
    <visual>
      <origin xyz="0 0 0" rpy="0 0 0" />
      <geometry>
        <mesh filename="../xhand1pro/xhand_right/meshes/right_hand_pinky_bend_link.STL" />
      </geometry>
      <material name="">
        <color rgba="0.055 0.055 0.063 1" />
      </material>
    </visual>
    <collision>
      <origin xyz="0 0 0" rpy="0 0 0" />
      <geometry>
        <mesh filename="../xhand1pro/xhand_right/meshes/right_hand_pinky_bend_link.STL" />
      </geometry>
    </collision>
  </link><joint name="right_hand_pinky_bend_joint" type="revolute">
    <origin xyz="-0.007 -0.011478 0.044292" rpy="0 0 0" />
    <parent link="right_hand_ltspalm_link" />
    <child link="right_hand_pinky_bend_link" />
    <axis xyz="-1 0 0" />
    <limit lower="-1.047" upper="0.175" effort="0.295" velocity="2" />
    <dynamics damping="0" friction="0" />
  </joint><link name="right_hand_pinky_rota_link1">
    <inertial>
      <origin xyz="-0.00460077029145276 2.64744040009285E-06 0.0165208303125737" rpy="0 0 0" />
      <mass value="0.07903209" />
      <inertia ixx="0.00001597" ixy="-0.00000011" ixz="-0.00000056" iyy="0.00001854" iyz="-0.00000003" izz="0.00000598" />
    </inertial>
    <visual>
      <origin xyz="0 0 0" rpy="0 0 0" />
      <geometry>
        <mesh filename="../xhand1pro/xhand_right/meshes/right_hand_pinky_rota_link1.STL" />
      </geometry>
      <material name="">
        <color rgba="0.055 0.055 0.063 1" />
      </material>
    </visual>
    <collision>
      <origin xyz="0 0 0" rpy="0 0 0" />
      <geometry>
        <mesh filename="../xhand1pro/xhand_right/meshes/right_hand_pinky_rota_link1.STL" />
      </geometry>
    </collision>
  </link><joint name="right_hand_pinky_rota_joint1" type="revolute">
    <origin xyz="0.0055 0 0.0233" rpy="0 0 0" />
    <parent link="right_hand_pinky_bend_link" />
    <child link="right_hand_pinky_rota_link1" />
    <axis xyz="0 1 0" />
    <limit lower="0" upper="1.571" effort="0.884" velocity="1.696" />
    <dynamics damping="0" friction="0" />
  </joint><link name="right_hand_pinky_rotaback_link1">
    <inertial>
      <origin xyz="-0.0199604212697446 -1.11555281101516E-06 -0.0153905493916474" rpy="0 0 0" />
      <mass value="0.001" />
      <inertia ixx="1e-8" ixy="0" ixz="0" iyy="1e-8" iyz="0" izz="1e-8" />
    </inertial>
    <visual>
      <origin xyz="0 0 0" rpy="0 0 0" />
      <geometry>
        <mesh filename="../xhand1pro/xhand_right/meshes/right_hand_pinky_rotaback_link1.STL" />
      </geometry>
      <material name="">
        <color rgba="0.941 0.941 0.941 1" />
      </material>
    </visual>
    <collision>
      <origin xyz="0 0 0" rpy="0 0 0" />
      <geometry>
        <mesh filename="../xhand1pro/xhand_right/meshes/right_hand_pinky_rotaback_link1.STL" />
      </geometry>
    </collision>
  </link><joint name="right_hand_pinky_rotaback_joint1" type="fixed">
    <origin xyz="0 0 0.0345" rpy="0 0 0" />
    <parent link="right_hand_pinky_rota_link1" />
    <child link="right_hand_pinky_rotaback_link1" />
    <axis xyz="0 0 0" />
    <dynamics damping="0" friction="0" />
  </joint><link name="right_hand_pinky_rota_link2">
    <inertial>
      <origin xyz="-0.00361835937101084 3.42636230876783E-05 0.0221934729698274" rpy="0 0 0" />
      <mass value="0.03780633" />
      <inertia ixx="0.00000528" ixy="0.00000001" ixz="0.00000013" iyy="0.00000557" iyz="0.00000005" izz="0.00000187" />
    </inertial>
    <visual>
      <origin xyz="0 0 0" rpy="0 0 0" />
      <geometry>
        <mesh filename="../xhand1pro/xhand_right/meshes/right_hand_pinky_rota_link2.STL" />
      </geometry>
      <material name="">
        <color rgba="0.055 0.055 0.063 1" />
      </material>
    </visual>
    <collision>
      <origin xyz="0 0 0" rpy="0 0 0" />
      <geometry>
        <mesh filename="../xhand1pro/xhand_right/meshes/right_hand_pinky_rota_link2.STL" />
      </geometry>
    </collision>
  </link><joint name="right_hand_pinky_rota_joint2" type="revolute">
    <origin xyz="0 0 0.0345" rpy="0 0 0" />
    <parent link="right_hand_pinky_rota_link1" />
    <child link="right_hand_pinky_rota_link2" />
    <axis xyz="0 1 0" />
    <limit lower="0" upper="1.571" effort="0.302" velocity="1.98" />
    <dynamics damping="0" friction="0" />
  </joint><link name="right_hand_pinky_rotaback_link2">
    <inertial>
      <origin xyz="-0.0111115592994485 -3.272105010238E-05 -0.0136070806526215" rpy="0 0 0" />
      <mass value="0.001" />
      <inertia ixx="1e-8" ixy="0" ixz="0" iyy="1e-8" iyz="0" izz="1e-8" />
    </inertial>
    <visual>
      <origin xyz="0 0 0" rpy="0 0 0" />
      <geometry>
        <mesh filename="../xhand1pro/xhand_right/meshes/right_hand_pinky_rotaback_link2.STL" />
      </geometry>
      <material name="">
        <color rgba="0.941 0.941 0.941 1" />
      </material>
    </visual>
    <collision>
      <origin xyz="0 0 0" rpy="0 0 0" />
      <geometry>
        <mesh filename="../xhand1pro/xhand_right/meshes/right_hand_pinky_rotaback_link2.STL" />
      </geometry>
    </collision>
  </link><joint name="right_hand_pinky_rotaback_joint2" type="fixed">
    <origin xyz="-0.00450000001858889 0 0.0374168958516306" rpy="0 0 0" />
    <parent link="right_hand_pinky_rota_link2" />
    <child link="right_hand_pinky_rotaback_link2" />
    <axis xyz="0 0 0" />
    <dynamics damping="0" friction="0" />
  </joint><link name="right_hand_pinky_rota_link3">
    <inertial>
      <origin xyz="-0.00042616959529944 2.78668800570564E-06 0.0156390621633755" rpy="0 0 0" />
      <mass value="0.00650707" />
      <inertia ixx="0.00000052" ixy="0.0" ixz="0.00000002" iyy="0.00000049" iyz="-0.00000001" izz="0.00000025" />
    </inertial>
    <visual>
      <origin xyz="0 0 0" rpy="0 0 0" />
      <geometry>
        <mesh filename="../xhand1pro/xhand_right/meshes/right_hand_pinky_rota_link3.STL" />
      </geometry>
      <material name="">
        <color rgba="0.055 0.055 0.063 1" />
      </material>
    </visual>
    <collision>
      <origin xyz="0 0 0" rpy="0 0 0" />
      <geometry>
        <mesh filename="../xhand1pro/xhand_right/meshes/right_hand_pinky_rota_link3.STL" />
      </geometry>
    </collision>
  </link><joint name="right_hand_pinky_rota_joint3" type="revolute">
    <origin xyz="-0.0045 0 0.037417" rpy="0 0 0" />
    <parent link="right_hand_pinky_rota_link2" />
    <child link="right_hand_pinky_rota_link3" />
    <axis xyz="0 1 0" />
    <limit lower="0" upper="1.571" effort="0.295" velocity="2" />
    <dynamics damping="0" friction="0" />
  </joint><link name="right_hand_pinky_rota_link4">
    <inertial>
      <origin xyz="3.90312782094782E-16 -2.4903690221123E-14 -5.55111512312578E-17" rpy="0 0 0" />
      <mass value="0.001" />
      <inertia ixx="1e-8" ixy="0" ixz="0" iyy="1e-8" iyz="0" izz="1e-8" />
    </inertial>
    <visual>
      <origin xyz="0 0 0" rpy="0 0 0" />
      <geometry>
        <mesh filename="../xhand1pro/xhand_right/meshes/right_hand_pinky_rota_link4.STL" />
      </geometry>
      <material name="">
        <color rgba="0.055 0.055 0.063 1" />
      </material>
    </visual>
    <collision>
      <origin xyz="0 0 0" rpy="0 0 0" />
      <geometry>
        <mesh filename="../xhand1pro/xhand_right/meshes/right_hand_pinky_rota_link4.STL" />
      </geometry>
    </collision>
  </link><joint name="right_hand_pinky_rota_joint4" type="fixed">
    <origin xyz="0.00791114209997283 0 0.018172818705828" rpy="0 0 0" />
    <parent link="right_hand_pinky_rota_link3" />
    <child link="right_hand_pinky_rota_link4" />
    <axis xyz="0 0 0" />
    <dynamics damping="0" friction="0" />
  </joint><link name="right_hand_pinky_rota_link5">
    <inertial>
      <origin xyz="4.04190569902596E-16 -2.4903690221123E-14 0" rpy="0 0 0" />
      <mass value="0.001" />
      <inertia ixx="1e-8" ixy="0" ixz="0" iyy="1e-8" iyz="0" izz="1e-8" />
    </inertial>
    <visual>
      <origin xyz="0 0 0" rpy="0 0 0" />
      <geometry>
        <mesh filename="../xhand1pro/xhand_right/meshes/right_hand_pinky_rota_link5.STL" />
      </geometry>
      <material name="">
        <color rgba="0.055 0.055 0.063 1" />
      </material>
    </visual>
    <collision>
      <origin xyz="0 0 0" rpy="0 0 0" />
      <geometry>
        <mesh filename="../xhand1pro/xhand_right/meshes/right_hand_pinky_rota_link5.STL" />
      </geometry>
    </collision>
  </link><joint name="right_hand_pinky_rota_joint5" type="fixed">
    <origin xyz="0 0 0.0312512504715699" rpy="0 0 0" />
    <parent link="right_hand_pinky_rota_link3" />
    <child link="right_hand_pinky_rota_link5" />
    <axis xyz="0 0 0" />
    <dynamics damping="0" friction="0" />
  </joint></robot>
