<?xml version="1.0" encoding="utf-8"?>
<!--GLB Source: https://github.com/sapien-sim/xarm7/tree/master/sapien_xarm7/xarm_urdf/xarm_description/meshes-->
<robot name="xarm7_umi_gripper">
  <link name="link_base">
    <inertial>
      <origin rpy="0 0 0" xyz="-0.021131 -0.0016302 0.056488"/>
      <mass value="0.88556"/>
      <inertia ixx="0.0030595" ixy="0.00012259" ixz="-0.00062705" iyy="0.0037783" iyz="0.00027023" izz="0.0020125"/>
    </inertial>
    <visual>
      <geometry>
        <mesh filename="../xarm7/meshes/visual/link_base.glb"/>
      </geometry>
      <origin rpy="0 0 0" xyz="0 0 0"/>
    </visual>
    <collision>
      <geometry>
        <mesh filename="../xarm7/meshes/collision/link_base.obj"/>
      </geometry>
      <origin rpy="0 0 0" xyz="0 0 0"/>
    </collision>
  </link>
  <link name="link1">
    <inertial>
      <origin rpy="0 0 0" xyz="-0.0002 0.02905 -0.01233"/>
      <mass value="2.382"/>
      <inertia ixx="0.0056905" ixy="-1.579e-05" ixz="5.125e-06" iyy="0.0049566" iyz="-0.000873378" izz="0.003316654"/>
    </inertial>
    <visual>
      <geometry>
        <mesh filename="../xarm7/meshes/visual/link1.glb"/>
      </geometry>
      <origin rpy="0 0 0" xyz="0 0 0"/>
    </visual>
    <collision>
      <geometry>
        <mesh filename="../xarm7/meshes/collision/link1.obj"/>
      </geometry>
      <origin rpy="0 0 0" xyz="0 0 0"/>
    </collision>
  </link>
  <joint name="joint1" type="revolute">
    <origin rpy="0 0 0" xyz="0 0 0.267"/>
    <parent link="link_base"/>
    <child link="link1"/>
    <axis xyz="0 0 1"/>
    <limit effort="50" lower="-6.28318530718" upper="6.28318530718" velocity="3.14"/>
    <dynamics damping="10" friction="1"/>
  </joint>
  <link name="link2">
    <inertial>
      <origin rpy="0 0 0" xyz="0.00022 -0.12856 0.01735"/>
      <mass value="1.869"/>
      <inertia ixx="0.0095989" ixy="1.541e-06" ixz="5.56e-06" iyy="0.00382472" iyz="-0.00317156" izz="0.007565669"/>
    </inertial>
    <visual>
      <geometry>
        <mesh filename="../xarm7/meshes/visual/link2.glb"/>
      </geometry>
      <origin rpy="0 0 0" xyz="0 0 0"/>
    </visual>
    <collision>
      <geometry>
        <mesh filename="../xarm7/meshes/collision/link2.obj"/>
      </geometry>
      <origin rpy="0 0 0" xyz="0 0 0"/>
    </collision>
  </link>
  <joint name="joint2" type="revolute">
    <origin rpy="-1.5708 0 0" xyz="0 0 0"/>
    <parent link="link1"/>
    <child link="link2"/>
    <axis xyz="0 0 1"/>
    <limit effort="50" lower="-2.059" upper="2.0944" velocity="3.14"/>
    <dynamics damping="10" friction="1"/>
  </joint>
  <link name="link3">
    <inertial>
      <origin rpy="0 0 0" xyz="0.0466 -0.02463 -0.00768"/>
      <mass value="1.6383"/>
      <inertia ixx="0.00310955" ixy="0.00030837" ixz="-0.00058453" iyy="0.00264483" iyz="0.000338893" izz="0.0026624"/>
    </inertial>
    <visual>
      <geometry>
        <mesh filename="../xarm7/meshes/visual/link3.glb"/>
      </geometry>
      <origin rpy="0 0 0" xyz="0 0 0"/>
    </visual>
    <collision>
      <geometry>
        <mesh filename="../xarm7/meshes/collision/link3.obj"/>
      </geometry>
      <origin rpy="0 0 0" xyz="0 0 0"/>
    </collision>
  </link>
  <joint name="joint3" type="revolute">
    <origin rpy="1.5708 0 0" xyz="0 -0.293 0"/>
    <parent link="link2"/>
    <child link="link3"/>
    <axis xyz="0 0 1"/>
    <limit effort="30" lower="-6.28318530718" upper="6.28318530718" velocity="3.14"/>
    <dynamics damping="5" friction="1"/>
  </joint>
  <link name="link4">
    <inertial>
      <origin rpy="0 0 0" xyz="0.07047 -0.11575 0.012"/>
      <mass value="1.7269"/>
      <inertia ixx="0.005889" ixy="0.00137112" ixz="0.00088143" iyy="0.00359703" iyz="-0.001762155" izz="0.00543244"/>
    </inertial>
    <visual>
      <geometry>
        <mesh filename="../xarm7/meshes/visual/link4.glb"/>
      </geometry>
      <origin rpy="0 0 0" xyz="0 0 0"/>
    </visual>
    <collision>
      <geometry>
        <mesh filename="../xarm7/meshes/collision/link4.obj"/>
      </geometry>
      <origin rpy="0 0 0" xyz="0 0 0"/>
    </collision>
  </link>
  <joint name="joint4" type="revolute">
    <origin rpy="1.5708 0 0" xyz="0.0525 0 0"/>
    <parent link="link3"/>
    <child link="link4"/>
    <axis xyz="0 0 1"/>
    <limit effort="30" lower="-0.19198" upper="3.927" velocity="3.14"/>
    <dynamics damping="5" friction="1"/>
  </joint>
  <link name="link5">
    <inertial>
      <origin rpy="0 0 0" xyz="-0.00032 0.01604 -0.026"/>
      <mass value="1.3203"/>
      <inertia ixx="0.00534665" ixy="1.5117e-05" ixz="-3.69e-07" iyy="0.0049779" iyz="-0.00022132" izz="0.0013624"/>
    </inertial>
    <visual>
      <geometry>
        <mesh filename="../xarm7/meshes/visual/link5.glb"/>
      </geometry>
      <origin rpy="0 0 0" xyz="0 0 0"/>
    </visual>
    <collision>
      <geometry>
        <mesh filename="../xarm7/meshes/collision/link5.obj"/>
      </geometry>
      <origin rpy="0 0 0" xyz="0 0 0"/>
    </collision>
  </link>
  <joint name="joint5" type="revolute">
    <origin rpy="1.5708 0 0" xyz="0.0775 -0.3425 0"/>
    <parent link="link4"/>
    <child link="link5"/>
    <axis xyz="0 0 1"/>
    <limit effort="30" lower="-6.28318530718" upper="6.28318530718" velocity="3.14"/>
    <dynamics damping="5" friction="1"/>
  </joint>
  <link name="link6">
    <inertial>
      <origin rpy="0 0 0" xyz="0.06469 0.03278 0.02141"/>
      <mass value="1.325"/>
      <inertia ixx="0.0014745" ixy="-0.000488" ixz="0.0002953" iyy="0.0019037" iyz="0.00014749" izz="0.0023652"/>
    </inertial>
    <visual>
      <geometry>
        <mesh filename="../xarm7/meshes/visual/link6.glb"/>
      </geometry>
      <origin rpy="0 0 0" xyz="0 0 0"/>
    </visual>
    <collision>
      <geometry>
        <mesh filename="../xarm7/meshes/collision/link6.obj"/>
      </geometry>
      <origin rpy="0 0 0" xyz="0 0 0"/>
    </collision>
  </link>
  <joint name="joint6" type="revolute">
    <origin rpy="1.5708 0 0" xyz="0 0 0"/>
    <parent link="link5"/>
    <child link="link6"/>
    <axis xyz="0 0 1"/>
    <limit effort="20" lower="-1.69297" upper="3.14159265359" velocity="3.14"/>
    <dynamics damping="2" friction="1"/>
  </joint>
  <link name="link7">
    <inertial>
      <origin rpy="0 0 0" xyz="0 -0.00677 -0.01098"/>
      <mass value="0.17"/>
      <inertia ixx="9.3e-05" ixy="-0.0" ixz="-0.0" iyy="5.87e-05" iyz="-3.6e-06" izz="0.000132"/>
    </inertial>
    <visual>
      <geometry>
        <mesh filename="../xarm7/meshes/visual/link7.glb"/>
      </geometry>
      <origin rpy="0 0 0" xyz="0 0 0"/>
    </visual>
    <collision>
      <geometry>
        <mesh filename="../xarm7/meshes/collision/link7.obj"/>
      </geometry>
      <origin rpy="0 0 0" xyz="0 0 0"/>
    </collision>
  </link>
  <joint name="joint7" type="revolute">
    <origin rpy="-1.5708 0 0" xyz="0.076 0.097 0"/>
    <parent link="link6"/>
    <child link="link7"/>
    <axis xyz="0 0 1"/>
    <limit effort="20" lower="-6.28318530718" upper="6.28318530718" velocity="3.14"/>
    <dynamics damping="2" friction="1"/>
  </joint>
  <joint name="joint_eef" type="fixed">
    <origin xyz="0 0 0.0125" rpy="0 0 0"/>
    <parent link="link7"/>
    <child link="body_1"/>
  </joint>
  <link name="body_1">
    <inertial>
      <origin xyz="0.0015967979364567948 0.003504282015459275 0.02287166630407777" rpy="2.172631339574884 -1.5218897734899373 -0.4655564621157525"/>
      <mass value="1.560126250423701"/>
      <inertia ixx="0.005530705291902967" iyy="0.0040921097044483426" izz="0.0027242058202118437" ixy="0" ixz="0" iyz="0"/>
    </inertial>
    <visual name="base_link">
      <origin xyz="0.00029036961018778486 0.009971136732595986 0.0249724306687446" rpy="0.11244518485826349 -1.473184401860941 1.4829997783243696"/>
      <geometry>
        <mesh filename="../umi_gripper/meshes/converted_base_link_ffffffff.obj"/>
      </geometry>
    </visual>
    <collision>
      <origin xyz="0.00029036961018778486 0.009971136732595986 0.0249724306687446" rpy="0.11244518485826349 -1.473184401860941 1.4829997783243696"/>
      <geometry>
        <mesh filename="../umi_gripper/meshes/converted_base_link_ffffffff.obj"/>
      </geometry>
    </collision>
    <visual name="base_link">
      <origin xyz="0.00029036961018778486 0.009971136732595986 0.0249724306687446" rpy="0.11244518485826349 -1.473184401860941 1.4829997783243696"/>
      <geometry>
        <mesh filename="../umi_gripper/meshes/converted_base_link_808080ff.obj"/>
      </geometry>
    </visual>
    <visual name="gopro">
      <origin xyz="0.018296779135748113 -0.07888114745584028 -0.003825781899764737" rpy="0.8735124240821344 1.478332652851687 -2.1979067150698626"/>
      <geometry>
        <mesh filename="../umi_gripper/meshes/converted_gopro_262626ff.obj"/>
      </geometry>
    </visual>
    <collision>
      <origin xyz="0.018296779135748113 -0.07888114745584028 -0.003825781899764737" rpy="0.8735124240821344 1.478332652851687 -2.1979067150698626"/>
      <geometry>
        <mesh filename="../umi_gripper/meshes/converted_gopro_262626ff.obj"/>
      </geometry>
    </collision>
    <visual name="gopro">
      <origin xyz="0.018296779135748113 -0.07888114745584028 -0.003825781899764737" rpy="0.8735124240821344 1.478332652851687 -2.1979067150698626"/>
      <geometry>
        <mesh filename="../umi_gripper/meshes/converted_gopro_808080ff.obj"/>
      </geometry>
    </visual>
  </link>
  <link name="left_finger_holder">
    <inertial>
      <origin xyz="-0.0613355 0.104073 -0.0013157" rpy="-1.1769009428563757 -1.3849810823943283 2.651450192417948"/>
      <mass value="0.080081"/>
      <inertia ixx="0.000104597" iyy="0.000102992" izz="1.90532e-05" ixy="0" ixz="0" iyz="0"/>
    </inertial>
    <visual name="left_finger_holder">
      <origin xyz="-0.0644068409846553 0.08112333887204844 -3.970886106907814e-05" rpy="1.2330756448677436 -0.3780366056799709 0.2839660278519583"/>
      <geometry>
        <mesh filename="../umi_gripper/meshes/converted_left_finger_holder_ffffffff.obj"/>
      </geometry>
    </visual>
    <collision>
      <origin xyz="-0.0644068409846553 0.08112333887204844 -3.970886106907814e-05" rpy="1.2330756448677436 -0.3780366056799709 0.2839660278519583"/>
      <geometry>
        <mesh filename="../umi_gripper/meshes/converted_left_finger_holder_ffffffff.obj"/>
      </geometry>
    </collision>
    <visual name="left_finger_holder">
      <origin xyz="-0.0644068409846553 0.08112333887204844 -3.970886106907814e-05" rpy="1.2330756448677436 -0.3780366056799709 0.2839660278519583"/>
      <geometry>
        <mesh filename="../umi_gripper/meshes/converted_left_finger_holder_808080ff.obj"/>
      </geometry>
    </visual>
    <visual name="left_finger">
      <origin xyz="-0.056436158389798194 0.12444200711018616 -0.002999999561905853" rpy="1.7143034299591546 1.5707963267948966 0.0"/>
      <geometry>
        <mesh filename="../umi_gripper/meshes/converted_left_finger_ebad3dff.obj"/>
      </geometry>
    </visual>
    <collision>
      <origin xyz="-0.056436158389798194 0.12444200711018616 -0.002999999561905853" rpy="1.7143034299591546 1.5707963267948966 0.0"/>
      <geometry>
        <mesh filename="../umi_gripper/meshes/converted_left_finger_ebad3dff.obj"/>
      </geometry>
    </collision>
    <visual name="left_finger">
      <origin xyz="-0.056436158389798194 0.12444200711018616 -0.002999999561905853" rpy="1.7143034299591546 1.5707963267948966 0.0"/>
      <geometry>
        <mesh filename="../umi_gripper/meshes/converted_left_finger_808080ff.obj"/>
      </geometry>
    </visual>
  </link>
  <link name="left_finger_joint_jointbody">
    <inertial>
      <origin xyz="0.0 0.0 0.0" rpy="0.0 0.0 0.0"/>
      <mass value="0.001"/>
      <inertia ixx="1e-09" iyy="1e-09" izz="1e-09" ixy="0" ixz="0" iyz="0"/>
    </inertial>
  </link>
  <joint type="prismatic" name="left_finger_joint">
    <parent link="body_1"/>
    <child link="left_finger_joint_jointbody"/>
    <origin xyz="0.0 0.0 0.0" rpy="1.5707963267948963 0.0 0.0"/>
    <axis xyz="1.0 0.0 0.0"/>
    <limit lower="0.0" upper="0.0417" effort="100" velocity="100"/>
  </joint>
  <joint type="fixed" name="left_finger_joint_offset">
    <parent link="left_finger_joint_jointbody"/>
    <child link="left_finger_holder"/>
    <origin xyz="-0.0 -0.0 -0.0" rpy="0.0 0.0 0.0"/>
  </joint>
  <link name="right_finger_holder">
    <inertial>
      <origin xyz="0.0613353 0.104073 -0.00131574" rpy="1.176946497676931 -1.384964732758037 0.49010502833437664"/>
      <mass value="0.080081"/>
      <inertia ixx="0.000104597" iyy="0.000102992" izz="1.90532e-05" ixy="0" ixz="0" iyz="0"/>
    </inertial>
    <visual name="right_finger_holder">
      <origin xyz="0.06440684101505119 0.08112333885440705 -3.970884378333247e-05" rpy="1.2330756411339179 0.3780366247775515 -0.2839660331644219"/>
      <geometry>
        <mesh filename="../umi_gripper/meshes/converted_right_finger_holder_ffffffff.obj"/>
      </geometry>
    </visual>
    <collision>
      <origin xyz="0.06440684101505119 0.08112333885440705 -3.970884378333247e-05" rpy="1.2330756411339179 0.3780366247775515 -0.2839660331644219"/>
      <geometry>
        <mesh filename="../umi_gripper/meshes/converted_right_finger_holder_ffffffff.obj"/>
      </geometry>
    </collision>
    <visual name="right_finger_holder">
      <origin xyz="0.06440684101505119 0.08112333885440705 -3.970884378333247e-05" rpy="1.2330756411339179 0.3780366247775515 -0.2839660331644219"/>
      <geometry>
        <mesh filename="../umi_gripper/meshes/converted_right_finger_holder_808080ff.obj"/>
      </geometry>
    </visual>
    <visual name="right_finger">
      <origin xyz="0.056436158389798194 0.12444200711018617 -0.0030000004380941452" rpy="1.7143034299591549 -1.5707963267948966 0.0"/>
      <geometry>
        <mesh filename="../umi_gripper/meshes/converted_right_finger_ebad3dff.obj"/>
      </geometry>
    </visual>
    <collision>
      <origin xyz="0.056436158389798194 0.12444200711018617 -0.0030000004380941452" rpy="1.7143034299591549 -1.5707963267948966 0.0"/>
      <geometry>
        <mesh filename="../umi_gripper/meshes/converted_right_finger_ebad3dff.obj"/>
      </geometry>
    </collision>
    <visual name="right_finger">
      <origin xyz="0.056436158389798194 0.12444200711018617 -0.0030000004380941452" rpy="1.7143034299591549 -1.5707963267948966 0.0"/>
      <geometry>
        <mesh filename="../umi_gripper/meshes/converted_right_finger_808080ff.obj"/>
      </geometry>
    </visual>
  </link>
  <link name="right_finger_joint_jointbody">
    <inertial>
      <origin xyz="0.0 0.0 0.0" rpy="0.0 0.0 0.0"/>
      <mass value="0.001"/>
      <inertia ixx="1e-09" iyy="1e-09" izz="1e-09" ixy="0" ixz="0" iyz="0"/>
    </inertial>
  </link>
  <joint type="prismatic" name="right_finger_joint">
    <parent link="body_1"/>
    <child link="right_finger_joint_jointbody"/>
    <origin xyz="0.0 0.0 0.0" rpy="1.5707963267948963 0.0 0.0"/>
    <axis xyz="-1.0 0.0 0.0"/>
    <limit lower="0.0" upper="0.0417" effort="100" velocity="100"/>
    <mimic joint="left_finger_joint" multiplier="1.0" offset="0.0"/>
  </joint>
  <joint type="fixed" name="right_finger_joint_offset">
    <parent link="right_finger_joint_jointbody"/>
    <child link="right_finger_holder"/>
    <origin xyz="-0.0 -0.0 -0.0" rpy="0.0 0.0 0.0"/>
  </joint>
</robot>
